Workbook

Sheet Summary
B2: Acme Corp — Model Summary & Dashboard
B3: ($ in millions, except per-share data; illustrative inputs)
B5: Active Scenario (change toggles on the Assumptions tab, cells C6:C9)
B6: Revenue growth case | C6: =Assumptions!C6 -> Base
B7: Discount rate (WACC) case | C7: =Assumptions!C7 -> Base
B8: Terminal value method | C8: =Assumptions!C8 -> Perpetuity Growth
B9: Mid-year convention | C9: =Assumptions!C9 -> Yes
B11: Valuation Output
B12: WACC | C12: =DCF!C6 -> 0.1031
B13: Terminal growth rate | C13: =DCF!C7 -> 0.025
B14: Enterprise value ($mm) | C14: =DCF!C43 -> 823.45412
B15: Equity value ($mm) | C15: =DCF!C47 -> 733.45412
B16: Implied share price ($) | C16: =DCF!C49 -> 14.669082
B17: Current share price ($) | C17: =DCF!C50 -> 12
B18: Implied upside / (downside) | C18: =DCF!C51 -> 0.22242353
B19: Revenue CAGR 2025A–2030E | C19: =('Income Statement'!H6/'Income Statement'!C6)^(1/5)-1 -> 0.05990565
B20: Model integrity | C20: =Checks!C13 -> ALL CHECKS PASS
B22: Financial Snapshot
B23: Fiscal Year Ending Dec-31 | C23: 2025A | D23: 2026E | E23: 2027E | F23: 2028E | G23: 2029E | H23: 2030E
B24: Revenue | C24: ='Income Statement'!C6 -> 500 | D24: ='Income Statement'!D6 -> 540 | E24: ='Income Statement'!E6 -> 577.8 | F24: ='Income Statement'!F6 -> 612.468 | G24: ='Income Statement'!G6 -> 643.0914 | H24: ='Income Statement'!H6 -> 668.81506
B25: EBITDA | C25: ='Income Statement'!C14 -> 95 | D25: ='Income Statement'!D14 -> 102.6 | E25: ='Income Statement'!E14 -> 110.9376 | F25: ='Income Statement'!F14 -> 118.81879 | G25: ='Income Statement'!G14 -> 126.04591 | H25: ='Income Statement'!H14 -> 132.42538
B26: EBITDA margin % | C26: ='Income Statement'!C15 -> 0.19 | D26: ='Income Statement'!D15 -> 0.19 | E26: ='Income Statement'!E15 -> 0.192 | F26: ='Income Statement'!F15 -> 0.194 | G26: ='Income Statement'!G15 -> 0.196 | H26: ='Income Statement'!H15 -> 0.198
B27: Net income | C27: ='Income Statement'!C23 -> 49.5 | D27: ='Income Statement'!D23 -> 54.633947 | E27: ='Income Statement'!E23 -> 61.056374 | F27: ='Income Statement'!F23 -> 67.376655 | G27: ='Income Statement'!G23 -> 73.512264 | H27: ='Income Statement'!H23 -> 79.3496
B28: Diluted EPS ($) | C28: ='Income Statement'!C26 -> 0.99 | D28: ='Income Statement'!D26 -> 1.0926789 | E28: ='Income Statement'!E26 -> 1.2211275 | F28: ='Income Statement'!F26 -> 1.3475331 | G28: ='Income Statement'!G26 -> 1.4702453 | H28: ='Income Statement'!H26 -> 1.586992
B29: Unlevered free cash flow | D29: =DCF!D24 -> 50.700685 | E29: =DCF!E24 -> 55.425748 | F29: =DCF!F24 -> 61.561424 | G29: =DCF!G24 -> 67.603463 | H29: =DCF!H24 -> 72.735575
B30: Ending cash | C30: ='Balance Sheet'!C7 -> 60 | D30: ='Balance Sheet'!D7 -> 76.445756 | E30: ='Balance Sheet'!E7 -> 96.391053 | F30: ='Balance Sheet'!F7 -> 121.32319 | G30: ='Balance Sheet'!G7 -> 151.27355 | H30: ='Balance Sheet'!H7 -> 185.47891
B31: Total debt | C31: ='Balance Sheet'!C19+'Balance Sheet'!C21 -> 150 | D31: ='Balance Sheet'!D19+'Balance Sheet'!D21 -> 132.78791 | E31: ='Balance Sheet'!E19+'Balance Sheet'!E21 -> 114.33156 | F31: ='Balance Sheet'!F19+'Balance Sheet'!F21 -> 94.541003 | G31: ='Balance Sheet'!G19+'Balance Sheet'!G21 -> 73.319782 | H31: ='Balance Sheet'!H19+'Balance Sheet'!H21 -> 50.564476
B54: Tab Guide
B55: Assumptions | C55: Scenario toggles (growth & WACC cases, TV method, mid-year), operating drivers, financing & valuation inputs
B56: Income Statement | C56: Revenue build through EPS; interest from Debt Schedule, interest income on opening cash
B57: Balance Sheet | C57: Working capital from days/percent drivers; cash from Cash Flow; debt from Debt Schedule
B58: Cash Flow | C58: Indirect method; ending cash links to Balance Sheet
B59: Debt Schedule | C59: Level-payment term loan amortization (PMT), annual roll-up via SUMIFS, current vs. long-term split
B60: DCF | C60: UFCF, perpetuity & exit-multiple terminal values, EV-to-equity bridge, two sensitivity grids
B61: Checks | C61: Balance, cash tie-out, debt tie-out, retained earnings roll-forward, WACC > g

Sheet Assumptions
B2: Acme Corp — Assumptions & Scenario Toggles
B3: ($ in millions, except per-share data; illustrative inputs)
B5: Scenario Toggles | C5: Selection | D5: Index
B6: Revenue growth case | C6: Base | D6: =MATCH(C6,$B$13:$B$15,0) -> 2
B7: Discount rate (WACC) case | C7: Base | D7: =MATCH(C7,$C$19:$E$19,0) -> 2
B8: Terminal value method | C8: Perpetuity Growth | D8: =IF(C8="Perpetuity Growth",1,2) -> 1
B9: Mid-year discounting convention | C9: Yes | D9: =IF(C9="Yes",1,0) -> 1
B11: Revenue Growth Scenarios (YoY %)
B12: Case | D12: 2026E | E12: 2027E | F12: 2028E | G12: 2029E | H12: 2030E | I12: Terminal g
B13: Downside | D13: 0.03 | E13: 0.03 | F13: 0.025 | G13: 0.02 | H13: 0.02 | I13: 0.015
B14: Base | D14: 0.08 | E14: 0.07 | F14: 0.06 | G14: 0.05 | H14: 0.04 | I14: 0.025
B15: Upside | D15: 0.14 | E15: 0.12 | F15: 0.1 | G15: 0.08 | H15: 0.06 | I15: 0.03
B16: Live revenue growth (selected case) | D16: =INDEX(D13:D15,$D$6) -> 0.08 | E16: =INDEX(E13:E15,$D$6) -> 0.07 | F16: =INDEX(F13:F15,$D$6) -> 0.06 | G16: =INDEX(G13:G15,$D$6) -> 0.05 | H16: =INDEX(H13:H15,$D$6) -> 0.04 | I16: =INDEX(I13:I15,$D$6) -> 0.025
B18: Discount Rate (WACC) Scenarios — CAPM Build
B19: Component | C19: Low | D19: Base | E19: High | F19: Live
B20: Risk-free rate | C20: 0.04 | D20: 0.0425 | E20: 0.045 | F20: =INDEX(C20:E20,$D$7) -> 0.0425
B21: Levered beta | C21: 1 | D21: 1.15 | E21: 1.3 | F21: =INDEX(C21:E21,$D$7) -> 1.15
B22: Equity risk premium | C22: 0.05 | D22: 0.055 | E22: 0.06 | F22: =INDEX(C22:E22,$D$7) -> 0.055
B23: Size / company-specific premium | C23: 0.005 | D23: 0.01 | E23: 0.015 | F23: =INDEX(C23:E23,$D$7) -> 0.01
B24: Pre-tax cost of debt | C24: 0.06 | D24: 0.07 | E24: 0.08 | F24: =INDEX(C24:E24,$D$7) -> 0.07
B25: Target debt / total capital | C25: 0.2 | D25: 0.2 | E25: 0.2 | F25: =INDEX(C25:E25,$D$7) -> 0.2
B26: Cost of equity (Rf + β × ERP + premium) | C26: =C20+C21*C22+C23 -> 0.095 | D26: =D20+D21*D22+D23 -> 0.11575 | E26: =E20+E21*E22+E23 -> 0.138 | F26: =F20+F21*F22+F23 -> 0.11575
B27: After-tax cost of debt | C27: =C24*(1-$C$54) -> 0.045 | D27: =D24*(1-$C$54) -> 0.0525 | E27: =E24*(1-$C$54) -> 0.06 | F27: =F24*(1-$C$54) -> 0.0525
B28: WACC | C28: =(1-C25)*C26+C25*C27 -> 0.085 | D28: =(1-D25)*D26+D25*D27 -> 0.1031 | E28: =(1-E25)*E26+E25*E27 -> 0.1224 | F28: =(1-F25)*F26+F25*F27 -> 0.1031
B30: Operating Assumptions (projection years)
B31: Driver | D31: 2026E | E31: 2027E | F31: 2028E | G31: 2029E | H31: 2030E
B32: COGS (% of revenue) | D32: 0.55 | E32: 0.55 | F32: 0.55 | G32: 0.55 | H32: 0.55
B33: SG&A (% of revenue) | D33: 0.18 | E33: 0.178 | F33: 0.176 | G33: 0.174 | H33: 0.172
B34: R&D (% of revenue) | D34: 0.08 | E34: 0.08 | F34: 0.08 | G34: 0.08 | H34: 0.08
B35: D&A (% of revenue) | D35: 0.04 | E35: 0.04 | F35: 0.04 | G35: 0.04 | H35: 0.04
B36: Capital expenditures (% of revenue) | D36: 0.05 | E36: 0.05 | F36: 0.048 | G36: 0.046 | H36: 0.045
B37: Effective tax rate | D37: 0.25 | E37: 0.25 | F37: 0.25 | G37: 0.25 | H37: 0.25
B38: Days sales outstanding (DSO) | D38: 45 | E38: 45 | F38: 45 | G38: 45 | H38: 45
B39: Days inventory outstanding (DIO, on COGS) | D39: 60 | E39: 60 | F39: 60 | G39: 60 | H39: 60
B40: Days payable outstanding (DPO, on COGS) | D40: 40 | E40: 40 | F40: 40 | G40: 40 | H40: 40
B41: Prepaid & other current assets (% of revenue) | D41: 0.02 | E41: 0.02 | F41: 0.02 | G41: 0.02 | H41: 0.02
B42: Accrued liabilities (% of revenue) | D42: 0.05 | E42: 0.05 | F42: 0.05 | G42: 0.05 | H42: 0.05
B43: Dividend payout (% of net income) | D43: 0.2 | E43: 0.2 | F43: 0.2 | G43: 0.2 | H43: 0.2
... B45: Equity issuance / (buyback) ($mm) | D45: 0 | E45: 0 | F45: 0 | G45: 0 | H45: 0
B47: Financing & Valuation Inputs
...

Sheet Debt Schedule
B2: Acme Corp — Term Loan Amortization Schedule
B3: ($ in millions, except per-share data; illustrative inputs)
B5: Loan Terms
B6: Principal ($mm) | C6: =Assumptions!C48 -> 150
B7: Annual interest rate | C7: =Assumptions!C49 -> 0.07
B8: Tenor (years) | C8: =Assumptions!C50 -> 7
B9: Payments per year | C9: =Assumptions!C51 -> 12
B10: Total number of payments | C10: =C8*C9 -> 84
B11: Periodic interest rate | C11: =C7/C9 -> 0.0058333333
B12: Level periodic payment (PMT) | C12: =PMT(C11,C10,-C6) -> 2.263902
B13: First payment date | C13: =Assumptions!C52 -> 46053
B14: Annual debt service | C14: =C12*C9 -> 27.166824
B16: Annual Summary
B17: Fiscal Year Ending Dec-31 | C17: 2025A | D17: 2026E | E17: 2027E | F17: 2028E | G17: 2029E | H17: 2030E
B18: Calendar year (helper) | C18: =YEAR(Assumptions!C56) -> 2025 | D18: =C18+1 -> 2026 | E18: =D18+1 -> 2027 | F18: =E18+1 -> 2028 | G18: =F18+1 -> 2029 | H18: =G18+1 -> 2030
B19: Beginning balance | D19: =C23 -> 150 | E19: =D23 -> 132.78791 | F19: =E23 -> 114.33156 | G19: =F23 -> 94.541003 | H19: =G23 -> 73.319782
B20: Interest expense | D20: =SUMIFS($G$30:$G$149,$D$30:$D$149,D18) -> 9.9547375 | E20: =SUMIFS($G$30:$G$149,$D$30:$D$149,E18) -> 8.7104744 | F20: =SUMIFS($G$30:$G$149,$D$30:$D$149,F18) -> 7.3762634 | G20: =SUMIFS($G$30:$G$149,$D$30:$D$149,G18) -> 5.9456022 | H20: =SUMIFS($G$30:$G$149,$D$30:$D$149,H18) -> 4.4115183
B21: Scheduled principal repayment | D21: =SUMIFS($H$30:$H$149,$D$30:$D$149,D18) -> 17.212086 | E21: =SUMIFS($H$30:$H$149,$D$30:$D$149,E18) -> 18.45635 | F21: =SUMIFS($H$30:$H$149,$D$30:$D$149,F18) -> 19.790561 | G21: =SUMIFS($H$30:$H$149,$D$30:$D$149,G18) -> 21.221222 | H21: =SUMIFS($H$30:$H$149,$D$30:$D$149,H18) -> 22.755306
B22: Total debt service | D22: =D20+D21 -> 27.166824 | E22: =E20+E21 -> 27.166824 | F22: =F20+F21 -> 27.166824 | G22: =G20+G21 -> 27.166824 | H22: =H20+H21 -> 27.166824
B23: Ending balance | C23: =C6 -> 150 | D23: =D19-D21 -> 132.78791 | E23: =E19-E21 -> 114.33156 | F23: =F19-F21 -> 94.541003 | G23: =G19-G21 -> 73.319782 | H23: =H19-H21 -> 50.564476
B24: Current portion (next-year principal) | C24: =SUMIFS($H$30:$H$149,$D$30:$D$149,C18+1) -> 17.212086 | D24: =SUMIFS($H$30:$H$149,$D$30:$D$149,D18+1) -> 18.45635 | E24: =SUMIFS($H$30:$H$149,$D$30:$D$149,E18+1) -> 19.790561 | F24: =SUMIFS($H$30:$H$149,$D$30:$D$149,F18+1) -> 21.221222 | G24: =SUMIFS($H$30:$H$149,$D$30:$D$149,G18+1) -> 22.755306 | H24: =SUMIFS($H$30:$H$149,$D$30:$D$149,H18+1) -> 24.400289
B25: Long-term portion | C25: =C23-C24 -> 132.78791 | D25: =D23-D24 -> 114.33156 | E25: =E23-E24 -> 94.541003 | F25: =F23-F24 -> 73.319782 | G25: =G23-G24 -> 50.564476 | H25: =H23-H24 -> 26.164187
B27: Periodic Amortization Schedule (capacity 120 periods; rows beyond tenor show zero)
B29: Period | C29: Payment Date | D29: Year | E29: Beginning Balance | F29: Payment | G29: Interest | H29: Principal | I29: Ending Balance
B30: 1 | C30: =IF(B30>$C$10,"",EDATE($C$13,(B30-1)*12/$C$9)) -> 46053 | D30: =IF(B30>$C$10,"",YEAR(C30)) -> 2026 | E30: =IF(B30>$C$10,0,$C$6) -> 150 | F30: =IF(B30>$C$10,0,$C$12) -> 2.263902 | G30: =E30*$C$11 -> 0.875 | H30: =F30-G30 -> 1.388902 | I30: =E30-H30 -> 148.6111
B31: =B30+1 -> 2 | C31: =IF(B31>$C$10,"",EDATE($C$13,(B31-1)*12/$C$9)) -> 46081 | D31: =IF(B31>$C$10,"",YEAR(C31)) -> 2026 | E31: =IF(B31>$C$10,0,I30) -> 148.6111 | F31: =IF(B31>$C$10,0,$C$12) -> 2.263902 | G31: =E31*$C$11 -> 0.86689807 | H31: =F31-G31 -> 1.3970039 | I31: =E31-H31 -> 147.21409
B32: =B31+1 -> 3 | C32: =IF(B32>$C$10,"",EDATE($C$13,(B32-1)*12/$C$9)) -> 46112 | D32: =IF(B32>$C$10,"",YEAR(C32)) -> 2026 | E32: =IF(B32>$C$10,0,I31) -> 147.21409 | F32: =IF(B32>$C$10,0,$C$12) -> 2.263902 | G32: =E32*$C$11 -> 0.85874888 | H32: =F32-G32 -> 1.4051531 | I32: =E32-H32 -> 145.80894
B33: =B32+1 -> 4 | C33: =IF(B33>$C$10,"",EDATE($C$13,(B33-1)*12/$C$9)) -> 46142 | D33: =IF(B33>$C$10,"",YEAR(C33)) -> 2026 | E33: =IF(B33>$C$10,0,I32) -> 145.80894 | F33: =IF(B33>$C$10,0,$C$12) -> 2.263902 | G33: =E33*$C$11 -> 0.85055216 | H33: =F33-G33 -> 1.4133498 | I33: =E33-H33 -> 144.39559
B34: =B33+1 -> 5 | C34: =IF(B34>$C$10,"",EDATE($C$13,(B34-1)*12/$C$9)) -> 46173 | D34: =IF(B34>$C$10,"",YEAR(C34)) -> 2026 | E34: =IF(B34>$C$10,0,I33) -> 144.39559 | F34: =IF(B34>$C$10,0,$C$12) -> 2.263902 | G34: =E34*$C$11 -> 0.84230761 | H34: =F34-G34 -> 1.4215944 | I34: =E34-H34 -> 142.974
B35: =B34+1 -> 6 | C35: =IF(B35>$C$10,"",EDATE($C$13,(B35-1)*12/$C$9)) -> 46203 | D35: =IF(B35>$C$10,"",YEAR(C35)) -> 2026 | E35: =IF(B35>$C$10,0,I34) -> 142.974 | F35: =IF(B35>$C$10,0,$C$12) -> 2.263902 | G35: =E35*$C$11 -> 0.83401498 | H35: =F35-G35 -> 1.429887 | I35: =E35-H35 -> 141.54411
B36: =B35+1 -> 7 | C36: =IF(B36>$C$10,"",EDATE($C$13,(B36-1)*12/$C$9)) -> 46234 | D36: =IF(B36>$C$10,"",YEAR(C36)) -> 2026 | E36: =IF(B36>$C$10,0,I35) -> 141.54411 | F36: =IF(B36>$C$10,0,$C$12) -> 2.263902 | G36: =E36*$C$11 -> 0.82567397 | H36: =F36-G36 -> 1.438228 | I36: =E36-H36 -> 140.10588
B37: =B36+1 -> 8 | C37: =IF(B37>$C$10,"",EDATE($C$13,(B37-1)*12/$C$9)) -> 46265 | D37: =IF(B37>$C$10,"",YEAR(C37)) -> 2026 | E37: =IF(B37>$C$10,0,I36) -> 140.10588 | F37: =IF(B37>$C$10,0,$C$12) -> 2.263902 | G37: =E37*$C$11 -> 0.81728431 | H37: =F37-G37 -> 1.4466177 | I37: =E37-H37 -> 138.65926
B38: =B37+1 -> 9 | C38: =IF(B38>$C$10,"",EDATE($C$13,(B38-1)*12/$C$9)) -> 46295 | D38: =IF(B38>$C$10,"",YEAR(C38)) -> 2026 | E38: =IF(B38>$C$10,0,I37) -> 138.65926 | F38: =IF(B38>$C$10,0,$C$12) -> 2.263902 | G38: =E38*$C$11 -> 0.80884571 | H38: =F38-G38 -> 1.4550563 | I38: =E38-H38 -> 137.20421
B39: =B38+1 -> 10 | C39: =IF(B39>$C$10,"",EDATE($C$13,(B39-1)*12/$C$9)) -> 46326 | D39: =IF(B39>$C$10,"",YEAR(C39)) -> 2026 | E39: =IF(B39>$C$10,0,I38) -> 137.20421 | F39: =IF(B39>$C$10,0,$C$12) -> 2.263902 | G39: =E39*$C$11 -> 0.80035788 | H39: =F39-G39 -> 1.4635441 | I39: =E39-H39 -> 135.74066
B40: =B39+1 -> 11 | C40: =IF(B40>$C$10,"",EDATE($C$13,(B40-1)*12/$C$9)) -> 46356 | D40: =IF(B40>$C$10,"",YEAR(C40)) -> 2026 | E40: =IF(B40>$C$10,0,I39) -> 135.74066 | F40: =IF(B40>$C$10,0,$C$12) -> 2.263902 | G40: =E40*$C$11 -> 0.79182054 | H40: =F40-G40 -> 1.4720815 | I40: =E40-H40 -> 134.26858
B41: =B40+1 -> 12 | C41: =IF(B41>$C$10,"",EDATE($C$13,(B41-1)*12/$C$9)) -> 46387 | D41: =IF(B41>$C$10,"",YEAR(C41)) -> 2026 | E41: =IF(B41>$C$10,0,I40) -> 134.26858 | F41: =IF(B41>$C$10,0,$C$12) -> 2.263902 | G41: =E41*$C$11 -> 0.7832334 | H41: =F41-G41 -> 1.4806686 | I41: =E41-H41 -> 132.78791
B42: =B41+1 -> 13 | C42: =IF(B42>$C$10,"",EDATE($C$13,(B42-1)*12/$C$9)) -> 46418 | D42: =IF(B42>$C$10,"",YEAR(C42)) -> 2027 | E42: =IF(B42>$C$10,0,I41) -> 132.78791 | F42: =IF(B42>$C$10,0,$C$12) -> 2.263902 | G42: =E42*$C$11 -> 0.77459616 | H42: =F42-G42 -> 1.4893058 | I42: =E42-H42 -> 131.29861
... B149: =B148+1 -> 120 | C149: =IF(B149>$C$10,"",EDATE($C$13,(B149-1)*12/$C$9)) | D149: =IF(B149>$C$10,"",YEAR(C149)) | E149: =IF(B149>$C$10,0,I148) -> 0 | F149: =IF(B149>$C$10,0,$C$12) -> 0 | G149: =E149*$C$11 -> 0 | H149: =F149-G149 -> 0 | I149: =E149-H149 -> 0

Sheet Income Statement
B2: Acme Corp — Income Statement
B3: ($ in millions, except per-share data; illustrative inputs)
B5: Fiscal Year Ending Dec-31 | C5: 2025A | D5: 2026E | E5: 2027E | F5: 2028E | G5: 2029E | H5: 2030E
B6: Revenue | C6: 500 | D6: =C6*(1+Assumptions!D16) -> 540 | E6: =D6*(1+Assumptions!E16) -> 577.8 | F6: =E6*(1+Assumptions!F16) -> 612.468 | G6: =F6*(1+Assumptions!G16) -> 643.0914 | H6: =G6*(1+Assumptions!H16) -> 668.81506
B7: % growth | D7: =D6/C6-1 -> 0.08 | E7: =E6/D6-1 -> 0.07 | F7: =F6/E6-1 -> 0.06 | G7: =G6/F6-1 -> 0.05 | H7: =H6/G6-1 -> 0.04
B8: Cost of goods sold | C8: 275 | D8: =D6*Assumptions!D32 -> 297 | E8: =E6*Assumptions!E32 -> 317.79 | F8: =F6*Assumptions!F32 -> 336.8574 | G8: =G6*Assumptions!G32 -> 353.70027 | H8: =H6*Assumptions!H32 -> 367.84828
B9: Gross profit | C9: =C6-C8 -> 225 | D9: =D6-D8 -> 243 | E9: =E6-E8 -> 260.01 | F9: =F6-F8 -> 275.6106 | G9: =G6-G8 -> 289.39113 | H9: =H6-H8 -> 300.96678
B10: Gross margin % | C10: =C9/C6 -> 0.45 | D10: =D9/D6 -> 0.45 | E10: =E9/E6 -> 0.45 | F10: =F9/F6 -> 0.45 | G10: =G9/G6 -> 0.45 | H10: =H9/H6 -> 0.45
B11: Selling, general & administrative | C11: 90 | D11: =D6*Assumptions!D33 -> 97.2 | E11: =E6*Assumptions!E33 -> 102.8484 | F11: =F6*Assumptions!F33 -> 107.79437 | G11: =G6*Assumptions!G33 -> 111.8979 | H11: =H6*Assumptions!H33 -> 115.03619
B12: Research & development | C12: 40 | D12: =D6*Assumptions!D34 -> 43.2 | E12: =E6*Assumptions!E34 -> 46.224 | F12: =F6*Assumptions!F34 -> 48.99744 | G12: =G6*Assumptions!G34 -> 51.447312 | H12: =H6*Assumptions!H34 -> 53.505204
B13: Total operating expenses | C13: =C11+C12 -> 130 | D13: =D11+D12 -> 140.4 | E13: =E11+E12 -> 149.0724 | F13: =F11+F12 -> 156.79181 | G13: =G11+G12 -> 163.34522 | H13: =H11+H12 -> 168.54139
B14: EBITDA | C14: =C9-C13 -> 95 | D14: =D9-D13 -> 102.6 | E14: =E9-E13 -> 110.9376 | F14: =F9-F13 -> 118.81879 | G14: =G9-G13 -> 126.04591 | H14: =H9-H13 -> 132.42538
B15: EBITDA margin % | C15: =C14/C6 -> 0.19 | D15: =D14/D6 -> 0.19 | E15: =E14/E6 -> 0.192 | F15: =F14/F6 -> 0.194 | G15: =G14/G6 -> 0.196 | H15: =H14/H6 -> 0.198
B16: Depreciation & amortization | C16: 20 | D16: =D6*Assumptions!D35 -> 21.6 | E16: =E6*Assumptions!E35 -> 23.112 | F16: =F6*Assumptions!F35 -> 24.49872 | G16: =G6*Assumptions!G35 -> 25.723656 | H16: =H6*Assumptions!H35 -> 26.752602
B17: EBIT (operating income) | C17: =C14-C16 -> 75 | D17: =D14-D16 -> 81 | E17: =E14-E16 -> 87.8256 | F17: =F14-F16 -> 94.320072 | G17: =G14-G16 -> 100.32226 | H17: =H14-H16 -> 105.67278
B18: EBIT margin % | C18: =C17/C6 -> 0.15 | D18: =D17/D6 -> 0.15 | E18: =E17/E6 -> 0.152 | F18: =F17/F6 -> 0.154 | G18: =G17/G6 -> 0.156 | H18: =H17/H6 -> 0.158
B19: Interest expense | C19: 10 | D19: ='Debt Schedule'!D20 -> 9.9547375 | E19: ='Debt Schedule'!E20 -> 8.7104744 | F19: ='Debt Schedule'!F20 -> 7.3762634 | G19: ='Debt Schedule'!G20 -> 5.9456022 | H19: ='Debt Schedule'!H20 -> 4.4115183
B20: Interest income | C20: 1 | D20: ='Balance Sheet'!C7*Assumptions!D44 -> 1.8 | E20: ='Balance Sheet'!D7*Assumptions!E44 -> 2.2933727 | F20: ='Balance Sheet'!E7*Assumptions!F44 -> 2.8917316 | G20: ='Balance Sheet'!F7*Assumptions!G44 -> 3.6396956 | H20: ='Balance Sheet'!G7*Assumptions!H44 -> 4.5382064
B21: Pre-tax income (EBT) | C21: =C17-C19+C20 -> 66 | D21: =D17-D19+D20 -> 72.845262 | E21: =E17-E19+E20 -> 81.408498 | F21: =F17-F19+F20 -> 89.83554 | G21: =G17-G19+G20 -> 98.016352 | H21: =H17-H19+H20 -> 105.79947
B22: Income tax expense | C22: 16.5 | D22: =MAX(0,D21*Assumptions!D37) -> 18.211316 | E22: =MAX(0,E21*Assumptions!E37) -> 20.352125 | F22: =MAX(0,F21*Assumptions!F37) -> 22.458885 | G22: =MAX(0,G21*Assumptions!G37) -> 24.504088 | H22: =MAX(0,H21*Assumptions!H37) -> 26.449867
B23: Net income | C23: =C21-C22 -> 49.5 | D23: =D21-D22 -> 54.633947 | E23: =E21-E22 -> 61.056374 | F23: =F21-F22 -> 67.376655 | G23: =G21-G22 -> 73.512264 | H23: =H21-H22 -> 79.3496
B24: Net margin % | C24: =C23/C6 -> 0.099 | D24: =D23/D6 -> 0.10117398 | E24: =E23/E6 -> 0.10567043 | F24: =F23/F6 -> 0.11000845 | G24: =G23/G6 -> 0.11431076 | H24: =H23/H6 -> 0.11864207
B25: Diluted shares outstanding (mm) | C25: =Assumptions!$C$53 -> 50 | D25: =Assumptions!$C$53 -> 50 | E25: =Assumptions!$C$53 -> 50 | F25: =Assumptions!$C$53 -> 50 | G25: =Assumptions!$C$53 -> 50 | H25: =Assumptions!$C$53 -> 50
B26: Diluted EPS ($) | C26: =C23/C25 -> 0.99 | D26: =D23/D25 -> 1.0926789 | E26: =E23/E25 -> 1.2211275 | F26: =F23/F25 -> 1.3475331 | G26: =G23/G25 -> 1.4702453 | H26: =H23/H25 -> 1.586992
B27: Dividends declared | C27: 10 | D27: =D23*Assumptions!D43 -> 10.926789 | E27: =E23*Assumptions!E43 -> 12.211275 | F27: =F23*Assumptions!F43 -> 13.475331 | G27: =G23*Assumptions!G43 -> 14.702453 | H27: =H23*Assumptions!H43 -> 15.86992
B28: Dividends per share ($) | C28: =C27/C25 -> 0.2 | D28: =D27/D25 -> 0.21853579 | E28: =E27/E25 -> 0.24422549 | F28: =F27/F25 -> 0.26950662 | G28: =G27/G25 -> 0.29404906 | H28: =H27/H25 -> 0.3173984

Sheet Balance Sheet
B2: Acme Corp — Balance Sheet
B3: ($ in millions, except per-share data; illustrative inputs)
B5: Fiscal Year Ending Dec-31 | C5: 2025A | D5: 2026E | E5: 2027E | F5: 2028E | G5: 2029E | H5: 2030E
B6: Assets
B7: Cash & equivalents | C7: 60 | D7: ='Cash Flow'!D28 -> 76.445756 | E7: ='Cash Flow'!E28 -> 96.391053 | F7: ='Cash Flow'!F28 -> 121.32319 | G7: ='Cash Flow'!G28 -> 151.27355 | H7: ='Cash Flow'!H28 -> 185.47891
B8: Accounts receivable | C8: 62 | D8: ='Income Statement'!D6*Assumptions!D38/365 -> 66.575342 | E8: ='Income Statement'!E6*Assumptions!E38/365 -> 71.235616 | F8: ='Income Statement'!F6*Assumptions!F38/365 -> 75.509753 | G8: ='Income Statement'!G6*Assumptions!G38/365 -> 79.285241 | H8: ='Income Statement'!H6*Assumptions!H38/365 -> 82.456651
B9: Inventory | C9: 45 | D9: ='Income Statement'!D8*Assumptions!D39/365 -> 48.821918 | E9: ='Income Statement'!E8*Assumptions!E39/365 -> 52.239452 | F9: ='Income Statement'!F8*Assumptions!F39/365 -> 55.373819 | G9: ='Income Statement'!G8*Assumptions!G39/365 -> 58.14251 | H9: ='Income Statement'!H8*Assumptions!H39/365 -> 60.468211
B10: Prepaid & other current assets | C10: 10 | D10: ='Income Statement'!D6*Assumptions!D41 -> 10.8 | E10: ='Income Statement'!E6*Assumptions!E41 -> 11.556 | F10: ='Income Statement'!F6*Assumptions!F41 -> 12.24936 | G10: ='Income Statement'!G6*Assumptions!G41 -> 12.861828 | H10: ='Income Statement'!H6*Assumptions!H41 -> 13.376301
B11: Total current assets | C11: =SUM(C7:C10) -> 177 | D11: =SUM(D7:D10) -> 202.64302 | E11: =SUM(E7:E10) -> 231.42212 | F11: =SUM(F7:F10) -> 264.45612 | G11: =SUM(G7:G10) -> 301.56312 | H11: =SUM(H7:H10) -> 341.78007
B12: Property, plant & equipment, net | C12: 180 | D12: =C12-'Cash Flow'!D17-'Income Statement'!D16 -> 185.4 | E12: =D12-'Cash Flow'!E17-'Income Statement'!E16 -> 191.178 | F12: =E12-'Cash Flow'!F17-'Income Statement'!F16 -> 196.07774 | G12: =F12-'Cash Flow'!G17-'Income Statement'!G16 -> 199.93629 | H12: =G12-'Cash Flow'!H17-'Income Statement'!H16 -> 203.28037
B13: Goodwill & intangibles | C13: 100 | D13: =C13 -> 100 | E13: =D13 -> 100 | F13: =E13 -> 100 | G13: =F13 -> 100 | H13: =G13 -> 100
B14: Total assets | C14: =C11+C12+C13 -> 457 | D14: =D11+D12+D13 -> 488.04302 | E14: =E11+E12+E13 -> 522.60012 | F14: =F11+F12+F13 -> 560.53386 | G14: =G11+G12+G13 -> 601.49942 | H14: =H11+H12+H13 -> 645.06044
B16: Liabilities & Shareholders' Equity
B17: Accounts payable | C17: 30 | D17: ='Income Statement'!D8*Assumptions!D40/365 -> 32.547945 | E17: ='Income Statement'!E8*Assumptions!E40/365 -> 34.826301 | F17: ='Income Statement'!F8*Assumptions!F40/365 -> 36.915879 | G17: ='Income Statement'!G8*Assumptions!G40/365 -> 38.761673 | H17: ='Income Statement'!H8*Assumptions!H40/365 -> 40.31214
B18: Accrued liabilities | C18: 25 | D18: ='Income Statement'!D6*Assumptions!D42 -> 27 | E18: ='Income Statement'!E6*Assumptions!E42 -> 28.89 | F18: ='Income Statement'!F6*Assumptions!F42 -> 30.6234 | G18: ='Income Statement'!G6*Assumptions!G42 -> 32.15457 | H18: ='Income Statement'!H6*Assumptions!H42 -> 33.440753
B19: Current portion of long-term debt | C19: ='Debt Schedule'!C24 -> 17.212086 | D19: ='Debt Schedule'!D24 -> 18.45635 | E19: ='Debt Schedule'!E24 -> 19.790561 | F19: ='Debt Schedule'!F24 -> 21.221222 | G19: ='Debt Schedule'!G24 -> 22.755306 | H19: ='Debt Schedule'!H24 -> 24.400289
B20: Total current liabilities | C20: =SUM(C17:C19) -> 72.212086 | D20: =SUM(D17:D19) -> 78.004295 | E20: =SUM(E17:E19) -> 83.506862 | F20: =SUM(F17:F19) -> 88.760501 | G20: =SUM(G17:G19) -> 93.671549 | H20: =SUM(H17:H19) -> 98.153182
B21: Long-term debt, net of current portion | C21: ='Debt Schedule'!C25 -> 132.78791 | D21: ='Debt Schedule'!D25 -> 114.33156 | E21: ='Debt Schedule'!E25 -> 94.541003 | F21: ='Debt Schedule'!F25 -> 73.319782 | G21: ='Debt Schedule'!G25 -> 50.564476 | H21: ='Debt Schedule'!H25 -> 26.164187
B22: Total liabilities | C22: =C20+C21 -> 205 | D22: =D20+D21 -> 192.33586 | E22: =E20+E21 -> 178.04787 | F22: =F20+F21 -> 162.08028 | G22: =G20+G21 -> 144.23602 | H22: =H20+H21 -> 124.31737
B23: Common stock & APIC | C23: 100 | D23: =C23+Assumptions!D45 -> 100 | E23: =D23+Assumptions!E45 -> 100 | F23: =E23+Assumptions!F45 -> 100 | G23: =F23+Assumptions!G45 -> 100 | H23: =G23+Assumptions!H45 -> 100
B24: Retained earnings | C24: 152 | D24: =C24+'Income Statement'!D23-'Income Statement'!D27 -> 195.70716 | E24: =D24+'Income Statement'!E23-'Income Statement'!E27 -> 244.55226 | F24: =E24+'Income Statement'!F23-'Income Statement'!F27 -> 298.45358 | G24: =F24+'Income Statement'!G23-'Income Statement'!G27 -> 357.26339 | H24: =G24+'Income Statement'!H23-'Income Statement'!H27 -> 420.74307
B25: Total shareholders' equity | C25: =C23+C24 -> 252 | D25: =D23+D24 -> 295.70716 | E25: =E23+E24 -> 344.55226 | F25: =F23+F24 -> 398.45358 | G25: =G23+G24 -> 457.26339 | H25: =H23+H24 -> 520.74307
B26: Total liabilities & equity | C26: =C22+C25 -> 457 | D26: =D22+D25 -> 488.04302 | E26: =E22+E25 -> 522.60012 | F26: =F22+F25 -> 560.53386 | G26: =G22+G25 -> 601.49942 | H26: =H22+H25 -> 645.06044
B28: Balance check (assets – liabilities & equity) | C28: =ROUND(C14-C26,4) -> 0 | D28: =ROUND(D14-D26,4) -> 0 | E28: =ROUND(E14-E26,4) -> 0 | F28: =ROUND(F14-F26,4) -> 0 | G28: =ROUND(G14-G26,4) -> 0 | H28: =ROUND(H14-H26,4) -> 0

Sheet Cash Flow
B2: Acme Corp — Cash Flow Statement
B3: ($ in millions, except per-share data; illustrative inputs)
B5: Fiscal Year Ending Dec-31 | C5: 2025A | D5: 2026E | E5: 2027E | F5: 2028E | G5: 2029E | H5: 2030E
B6: Operating Activities
B7: Net income | C7: Base year | D7: ='Income Statement'!D23 -> 54.633947 | E7: ='Income Statement'!E23 -> 61.056374 | F7: ='Income Statement'!F23 -> 67.376655 | G7: ='Income Statement'!G23 -> 73.512264 | H7: ='Income Statement'!H23 -> 79.3496
B8: Depreciation & amortization | D8: ='Income Statement'!D16 -> 21.6 | E8: ='Income Statement'!E16 -> 23.112 | F8: ='Income Statement'!F16 -> 24.49872 | G8: ='Income Statement'!G16 -> 25.723656 | H8: ='Income Statement'!H16 -> 26.752602
B9: (Increase) / decrease in accounts receivable | D9: ='Balance Sheet'!C8-'Balance Sheet'!D8 -> -4.5753425 | E9: ='Balance Sheet'!D8-'Balance Sheet'!E8 -> -4.660274 | F9: ='Balance Sheet'!E8-'Balance Sheet'!F8 -> -4.274137 | G9: ='Balance Sheet'!F8-'Balance Sheet'!G8 -> -3.7754877 | H9: ='Balance Sheet'!G8-'Balance Sheet'!H8 -> -3.1714096
B10: (Increase) / decrease in inventory | D10: ='Balance Sheet'!C9-'Balance Sheet'!D9 -> -3.8219178 | E10: ='Balance Sheet'!D9-'Balance Sheet'!E9 -> -3.4175342 | F10: ='Balance Sheet'!E9-'Balance Sheet'!F9 -> -3.1343671 | G10: ='Balance Sheet'!F9-'Balance Sheet'!G9 -> -2.768691 | H10: ='Balance Sheet'!G9-'Balance Sheet'!H9 -> -2.3257004
B11: (Increase) / decrease in prepaid & other | D11: ='Balance Sheet'!C10-'Balance Sheet'!D10 -> -0.8 | E11: ='Balance Sheet'!D10-'Balance Sheet'!E10 -> -0.756 | F11: ='Balance Sheet'!E10-'Balance Sheet'!F10 -> -0.69336 | G11: ='Balance Sheet'!F10-'Balance Sheet'!G10 -> -0.612468 | H11: ='Balance Sheet'!G10-'Balance Sheet'!H10 -> -0.51447312
B12: Increase / (decrease) in accounts payable | D12: ='Balance Sheet'!D17-'Balance Sheet'!C17 -> 2.5479452 | E12: ='Balance Sheet'!E17-'Balance Sheet'!D17 -> 2.2783562 | F12: ='Balance Sheet'!F17-'Balance Sheet'!E17 -> 2.0895781 | G12: ='Balance Sheet'!G17-'Balance Sheet'!F17 -> 1.845794 | H12: ='Balance Sheet'!H17-'Balance Sheet'!G17 -> 1.5504669
B13: Increase / (decrease) in accrued liabilities | D13: ='Balance Sheet'!D18-'Balance Sheet'!C18 -> 2 | E13: ='Balance Sheet'!E18-'Balance Sheet'!D18 -> 1.89 | F13: ='Balance Sheet'!F18-'Balance Sheet'!E18 -> 1.7334 | G13: ='Balance Sheet'!G18-'Balance Sheet'!F18 -> 1.53117 | H13: ='Balance Sheet'!H18-'Balance Sheet'!G18 -> 1.2861828
B14: Cash flow from operating activities | D14: =SUM(D7:D13) -> 71.584632 | E14: =SUM(E7:E13) -> 79.502922 | F14: =SUM(F7:F13) -> 87.596489 | G14: =SUM(G7:G13) -> 95.456237 | H14: =SUM(H7:H13) -> 102.92727
B16: Investing Activities
B17: Capital expenditures | D17: =-'Income Statement'!D6*Assumptions!D36 -> -27 | E17: =-'Income Statement'!E6*Assumptions!E36 -> -28.89 | F17: =-'Income Statement'!F6*Assumptions!F36 -> -29.398464 | G17: =-'Income Statement'!G6*Assumptions!G36 -> -29.582204 | H17: =-'Income Statement'!H6*Assumptions!H36 -> -30.096678
B18: Cash flow from investing activities | D18: =D17 -> -27 | E18: =E17 -> -28.89 | F18: =F17 -> -29.398464 | G18: =G17 -> -29.582204 | H18: =H17 -> -30.096678
B20: Financing Activities
B21: Term loan principal repayment | D21: =-'Debt Schedule'!D21 -> -17.212086 | E21: =-'Debt Schedule'!E21 -> -18.45635 | F21: =-'Debt Schedule'!F21 -> -19.790561 | G21: =-'Debt Schedule'!G21 -> -21.221222 | H21: =-'Debt Schedule'!H21 -> -22.755306
B22: Dividends paid | D22: =-'Income Statement'!D27 -> -10.926789 | E22: =-'Income Statement'!E27 -> -12.211275 | F22: =-'Income Statement'!F27 -> -13.475331 | G22: =-'Income Statement'!G27 -> -14.702453 | H22: =-'Income Statement'!H27 -> -15.86992
B23: Equity issuance / (buyback) | D23: =Assumptions!D45 -> 0 | E23: =Assumptions!E45 -> 0 | F23: =Assumptions!F45 -> 0 | G23: =Assumptions!G45 -> 0 | H23: =Assumptions!H45 -> 0
B24: Cash flow from financing activities | D24: =SUM(D21:D23) -> -28.138876 | E24: =SUM(E21:E23) -> -30.667624 | F24: =SUM(F21:F23) -> -33.265892 | G24: =SUM(G21:G23) -> -35.923675 | H24: =SUM(H21:H23) -> -38.625226
B26: Net change in cash | D26: =D14+D18+D24 -> 16.445756 | E26: =E14+E18+E24 -> 19.945297 | F26: =F14+F18+F24 -> 24.932134 | G26: =G14+G18+G24 -> 29.950358 | H26: =H14+H18+H24 -> 34.205366
B27: Beginning cash balance | D27: ='Balance Sheet'!C7 -> 60 | E27: ='Balance Sheet'!D7 -> 76.445756 | F27: ='Balance Sheet'!E7 -> 96.391053 | G27: ='Balance Sheet'!F7 -> 121.32319 | H27: ='Balance Sheet'!G7 -> 151.27355
B28: Ending cash balance | D28: =D26+D27 -> 76.445756 | E28: =E26+E27 -> 96.391053 | F28: =F26+F27 -> 121.32319 | G28: =G26+G27 -> 151.27355 | H28: =H26+H27 -> 185.47891
B30: Memo: Free cash flow (CFO + capex) | D30: =D14+D17 -> 44.584632 | E30: =E14+E17 -> 50.612922 | F30: =F14+F17 -> 58.198025 | G30: =G14+G17 -> 65.874033 | H30: =H14+H17 -> 72.830591
B31: Memo: Change in net working capital (sum of WC lines) | D31: =SUM(D9:D13) -> -4.6493151 | E31: =SUM(E9:E13) -> -4.6654521 | F31: =SUM(F9:F13) -> -4.278886 | G31: =SUM(G9:G13) -> -3.7796827 | H31: =SUM(H9:H13) -> -3.1749334

Sheet DCF
B2: Acme Corp — Discounted Cash Flow Valuation
B3: ($ in millions, except per-share data; illustrative inputs)
B5: Live Valuation Drivers (driven by Assumptions toggles)
B6: WACC (selected discount-rate case) | C6: =Assumptions!F28 -> 0.1031
B7: Terminal growth rate (selected growth case) | C7: =Assumptions!I16 -> 0.025
B8: Exit EV / EBITDA multiple | C8: =Assumptions!C55 -> 8
B9: Marginal tax rate | C9: =Assumptions!C54 -> 0.25
B10: Mid-year convention flag (1 = on) | C10: =Assumptions!D9 -> 1
B11: Terminal value method (1 = perpetuity, 2 = exit multiple) | C11: =Assumptions!D8 -> 1
B12: Active scenario | C12: ="Growth: "&Assumptions!C6&" | WACC: "&Assumptions!C7&" | TV: "&Assumptions!C8 -> Growth: Base | WACC: Base | TV: Perpetuity Growth
B14: Unlevered Free Cash Flow
B15: Fiscal Year Ending Dec-31 | D15: 2026E | E15: 2027E | F15: 2028E | G15: 2029E | H15: 2030E
B16: Revenue | D16: ='Income Statement'!D6 -> 540 | E16: ='Income Statement'!E6 -> 577.8 | F16: ='Income Statement'!F6 -> 612.468 | G16: ='Income Statement'!G6 -> 643.0914 | H16: ='Income Statement'!H6 -> 668.81506
B17: EBITDA | D17: ='Income Statement'!D14 -> 102.6 | E17: ='Income Statement'!E14 -> 110.9376 | F17: ='Income Statement'!F14 -> 118.81879 | G17: ='Income Statement'!G14 -> 126.04591 | H17: ='Income Statement'!H14 -> 132.42538
B18: EBIT | D18: ='Income Statement'!D17 -> 81 | E18: ='Income Statement'!E17 -> 87.8256 | F18: ='Income Statement'!F17 -> 94.320072 | G18: ='Income Statement'!G17 -> 100.32226 | H18: ='Income Statement'!H17 -> 105.67278
B19: Less: taxes on EBIT | D19: =-D18*$C$9 -> -20.25 | E19: =-E18*$C$9 -> -21.9564 | F19: =-F18*$C$9 -> -23.580018 | G19: =-G18*$C$9 -> -25.080565 | H19: =-H18*$C$9 -> -26.418195
B20: NOPAT | D20: =D18+D19 -> 60.75 | E20: =E18+E19 -> 65.8692 | F20: =F18+F19 -> 70.740054 | G20: =G18+G19 -> 75.241694 | H20: =H18+H19 -> 79.254584
B21: Plus: depreciation & amortization | D21: ='Income Statement'!D16 -> 21.6 | E21: ='Income Statement'!E16 -> 23.112 | F21: ='Income Statement'!F16 -> 24.49872 | G21: ='Income Statement'!G16 -> 25.723656 | H21: ='Income Statement'!H16 -> 26.752602
B22: Less: capital expenditures | D22: ='Cash Flow'!D17 -> -27 | E22: ='Cash Flow'!E17 -> -28.89 | F22: ='Cash Flow'!F17 -> -29.398464 | G22: ='Cash Flow'!G17 -> -29.582204 | H22: ='Cash Flow'!H17 -> -30.096678
B23: Less: increase in net working capital | D23: ='Cash Flow'!D31 -> -4.6493151 | E23: ='Cash Flow'!E31 -> -4.6654521 | F23: ='Cash Flow'!F31 -> -4.278886 | G23: ='Cash Flow'!G31 -> -3.7796827 | H23: ='Cash Flow'!H31 -> -3.1749334
B24: Unlevered free cash flow | D24: =D20+D21+D22+D23 -> 50.700685 | E24: =E20+E21+E22+E23 -> 55.425748 | F24: =F20+F21+F22+F23 -> 61.561424 | G24: =G20+G21+G22+G23 -> 67.603463 | H24: =H20+H21+H22+H23 -> 72.735575
B25: Projection year (t) | D25: 1 | E25: =D25+1 -> 2 | F25: =E25+1 -> 3 | G25: =F25+1 -> 4 | H25: =G25+1 -> 5
B26: Discount period (t – 0.5 if mid-year) | D26: =D25-0.5*$C$10 -> 0.5 | E26: =E25-0.5*$C$10 -> 1.5 | F26: =F25-0.5*$C$10 -> 2.5 | G26: =G25-0.5*$C$10 -> 3.5 | H26: =H25-0.5*$C$10 -> 4.5
B27: Discount factor | D27: =1/(1+$C$6)^D26 -> 0.95212191 | E27: =1/(1+$C$6)^E26 -> 0.8631329 | F27: =1/(1+$C$6)^F26 -> 0.78246116 | G27: =1/(1+$C$6)^G26 -> 0.70932931 | H27: =1/(1+$C$6)^H26 -> 0.64303264
B28: Present value of UFCF | D28: =D24*D27 -> 48.273233 | E28: =E24*E27 -> 47.839787 | F28: =F24*F27 -> 48.169423 | G28: =G24*G27 -> 47.953117 | H28: =H24*H27 -> 46.771349
B30: Terminal Value
B31: Final-year UFCF (2030E) | C31: =H24 -> 72.735575
B32: TV — perpetuity growth [UFCF × (1+g) / (WACC – g)] | C32: =IF(C6>C7,H24*(1+C7)/(C6-C7),NA()) -> 954.59622
B33: TV — exit multiple [2030E EBITDA × multiple] | C33: =H17*C8 -> 1059.403
B34: Selected terminal value | C34: =CHOOSE(C11,C32,C33) -> 954.59622
B35: TV discount factor (end of final year) | C35: =1/(1+C6)^H25 -> 0.61224547
B36: Present value of terminal value | C36: =C34*C35 -> 584.44721
B37: Implied exit multiple from perpetuity method | C37: =C32/H17 -> 7.2085594
B38: Implied perpetuity growth from exit-multiple method | C38: =(C33*C6-H24)/(C33+H24) -> 0.032230045
B40: Enterprise Value to Implied Share Price
B41: Sum of PV of UFCF (2026E–2030E) | C41: =SUM(D28:H28) -> 239.00691
B42: PV of terminal value | C42: =C36 -> 584.44721
B43: Enterprise value | C43: =C41+C42 -> 823.45412
B44: PV of terminal value as % of EV | C44: =C42/C43 -> 0.70975079
B45: Less: total debt (valuation date) | C45: =-('Balance Sheet'!C19+'Balance Sheet'!C21) -> -150
...

Sheet Checks
B2: Acme Corp — Model Integrity Checks
B3: ($ in millions, except per-share data; illustrative inputs)
B5: Fiscal Year Ending Dec-31 | C5: 2025A | D5: 2026E | E5: 2027E | F5: 2028E | G5: 2029E | H5: 2030E
B6: Balance sheet balances (abs diff < 0.001) | C6: =ABS('Balance Sheet'!C14-'Balance Sheet'!C26)<0.001 -> TRUE | D6: =ABS('Balance Sheet'!D14-'Balance Sheet'!D26)<0.001 -> TRUE | E6: =ABS('Balance Sheet'!E14-'Balance Sheet'!E26)<0.001 -> TRUE | F6: =ABS('Balance Sheet'!F14-'Balance Sheet'!F26)<0.001 -> TRUE | G6: =ABS('Balance Sheet'!G14-'Balance Sheet'!G26)<0.001 -> TRUE | H6: =ABS('Balance Sheet'!H14-'Balance Sheet'!H26)<0.001 -> TRUE
B7: Cash flow ending cash = balance sheet cash | D7: =ABS('Cash Flow'!D28-'Balance Sheet'!D7)<0.001 -> TRUE | E7: =ABS('Cash Flow'!E28-'Balance Sheet'!E7)<0.001 -> TRUE | F7: =ABS('Cash Flow'!F28-'Balance Sheet'!F7)<0.001 -> TRUE | G7: =ABS('Cash Flow'!G28-'Balance Sheet'!G7)<0.001 -> TRUE | H7: =ABS('Cash Flow'!H28-'Balance Sheet'!H7)<0.001 -> TRUE
B8: Debt schedule ending balance = BS total debt | C8: =ABS('Debt Schedule'!C23-'Balance Sheet'!C19-'Balance Sheet'!C21)<0.001 -> TRUE | D8: =ABS('Debt Schedule'!D23-'Balance Sheet'!D19-'Balance Sheet'!D21)<0.001 -> TRUE | E8: =ABS('Debt Schedule'!E23-'Balance Sheet'!E19-'Balance Sheet'!E21)<0.001 -> TRUE | F8: =ABS('Debt Schedule'!F23-'Balance Sheet'!F19-'Balance Sheet'!F21)<0.001 -> TRUE | G8: =ABS('Debt Schedule'!G23-'Balance Sheet'!G19-'Balance Sheet'!G21)<0.001 -> TRUE | H8: =ABS('Debt Schedule'!H23-'Balance Sheet'!H19-'Balance Sheet'!H21)<0.001 -> TRUE
B9: Cash balance non-negative | C9: ='Balance Sheet'!C7>=0 -> TRUE | D9: ='Balance Sheet'!D7>=0 -> TRUE | E9: ='Balance Sheet'!E7>=0 -> TRUE | F9: ='Balance Sheet'!F7>=0 -> TRUE | G9: ='Balance Sheet'!G7>=0 -> TRUE | H9: ='Balance Sheet'!H7>=0 -> TRUE
B10: Retained earnings roll-forward ties | D10: =ABS('Balance Sheet'!D24-'Balance Sheet'!C24-'Income Statement'!D23+'Income Statement'!D27)<0.001 -> TRUE | E10: =ABS('Balance Sheet'!E24-'Balance Sheet'!D24-'Income Statement'!E23+'Income Statement'!E27)<0.001 -> TRUE | F10: =ABS('Balance Sheet'!F24-'Balance Sheet'!E24-'Income Statement'!F23+'Income Statement'!F27)<0.001 -> TRUE | G10: =ABS('Balance Sheet'!G24-'Balance Sheet'!F24-'Income Statement'!G23+'Income Statement'!G27)<0.001 -> TRUE | H10: =ABS('Balance Sheet'!H24-'Balance Sheet'!G24-'Income Statement'!H23+'Income Statement'!H27)<0.001 -> TRUE
B11: WACC exceeds terminal growth rate | C11: =DCF!C6>DCF!C7 -> TRUE
B13: Overall model status | C13: =IF(AND(C6:H10,C11),"ALL CHECKS PASS","CHECK ERRORS") -> ALL CHECKS PASS
