Workbook
Name EM_1B: 'Event Map'!$F$6:$F$60
Name EM_2B: 'Event Map'!$G$6:$G$60
Name EM_3B: 'Event Map'!$H$6:$H$60
Name EM_AB: 'Event Map'!$D$6:$D$60
Name EM_BB: 'Event Map'!$J$6:$J$60
Name EM_DP: 'Event Map'!$O$6:$O$60
Name EM_H: 'Event Map'!$E$6:$E$60
Name EM_HBP: 'Event Map'!$L$6:$L$60
Name EM_HR: 'Event Map'!$I$6:$I$60
Name EM_IBB: 'Event Map'!$K$6:$K$60
Name EM_PA: 'Event Map'!$C$6:$C$60
Name EM_ROE: 'Event Map'!$P$6:$P$60
Name EM_SF: 'Event Map'!$M$6:$M$60
Name EM_SH: 'Event Map'!$N$6:$N$60
Name EM_Type: 'Event Map'!$B$6:$B$60
Name FIP_C: Lists!$C$10
Name MinBF: Lists!$C$12
Name MinPA: Lists!$C$11
Name pbp_Ball3: 'MLB-SAMPLE-PbP'!$AD$3:INDEX('MLB-SAMPLE-PbP'!$AD:$AD,pbp_LastRow)
Name pbp_BatHand: 'MLB-SAMPLE-PbP'!$J$3:INDEX('MLB-SAMPLE-PbP'!$J:$J,pbp_LastRow)
Name pbp_BatTeam: 'MLB-SAMPLE-PbP'!$G$3:INDEX('MLB-SAMPLE-PbP'!$G:$G,pbp_LastRow)
Name pbp_Batter: 'MLB-SAMPLE-PbP'!$H$3:INDEX('MLB-SAMPLE-PbP'!$H:$H,pbp_LastRow)
Name pbp_Catcher: 'MLB-SAMPLE-PbP'!$R$3:INDEX('MLB-SAMPLE-PbP'!$R:$R,pbp_LastRow)
Name pbp_CS: 'MLB-SAMPLE-PbP'!$AN$3:INDEX('MLB-SAMPLE-PbP'!$AN:$AN,pbp_LastRow)
Name pbp_Desc: 'MLB-SAMPLE-PbP'!$AR$3:INDEX('MLB-SAMPLE-PbP'!$AR:$AR,pbp_LastRow)
Name pbp_GameID: 'MLB-SAMPLE-PbP'!$B$3:INDEX('MLB-SAMPLE-PbP'!$B:$B,pbp_LastRow)
Name pbp_GameIDPrev: 'MLB-SAMPLE-PbP'!$B$2:INDEX('MLB-SAMPLE-PbP'!$B:$B,pbp_LastRow-1)
Name pbp_HitType: 'MLB-SAMPLE-PbP'!$AI$3:INDEX('MLB-SAMPLE-PbP'!$AI:$AI,pbp_LastRow)
Name pbp_Inning: 'MLB-SAMPLE-PbP'!$D$3:INDEX('MLB-SAMPLE-PbP'!$D:$D,pbp_LastRow)
Name pbp_InningPrev: 'MLB-SAMPLE-PbP'!$D$2:INDEX('MLB-SAMPLE-PbP'!$D:$D,pbp_LastRow-1)
Name pbp_LastRow: Lists!$C$6
Name pbp_On1B: 'MLB-SAMPLE-PbP'!$K$3:INDEX('MLB-SAMPLE-PbP'!$K:$K,pbp_LastRow)
Name pbp_On2B: 'MLB-SAMPLE-PbP'!$L$3:INDEX('MLB-SAMPLE-PbP'!$L:$L,pbp_LastRow)
Name pbp_On3B: 'MLB-SAMPLE-PbP'!$M$3:INDEX('MLB-SAMPLE-PbP'!$M:$M,pbp_LastRow)
Name pbp_Outs: 'MLB-SAMPLE-PbP'!$AL$3:INDEX('MLB-SAMPLE-PbP'!$AL:$AL,pbp_LastRow)
Name pbp_PB: 'MLB-SAMPLE-PbP'!$AP$3:INDEX('MLB-SAMPLE-PbP'!$AP:$AP,pbp_LastRow)
Name pbp_Pitcher: 'MLB-SAMPLE-PbP'!$O$3:INDEX('MLB-SAMPLE-PbP'!$O:$O,pbp_LastRow)
Name pbp_Pitches: 'MLB-SAMPLE-PbP'!$Z$3:INDEX('MLB-SAMPLE-PbP'!$Z:$Z,pbp_LastRow)
Name pbp_PitHand: 'MLB-SAMPLE-PbP'!$Q$3:INDEX('MLB-SAMPLE-PbP'!$Q:$Q,pbp_LastRow)
Name pbp_PitTeam: 'MLB-SAMPLE-PbP'!$N$3:INDEX('MLB-SAMPLE-PbP'!$N:$N,pbp_LastRow)
Name pbp_PlayType: 'MLB-SAMPLE-PbP'!$AJ$3:INDEX('MLB-SAMPLE-PbP'!$AJ:$AJ,pbp_LastRow)
Name pbp_Runs: 'MLB-SAMPLE-PbP'!$AK$3:INDEX('MLB-SAMPLE-PbP'!$AK:$AK,pbp_LastRow)
Name pbp_SB: 'MLB-SAMPLE-PbP'!$AM$3:INDEX('MLB-SAMPLE-PbP'!$AM:$AM,pbp_LastRow)
Name pbp_Seq: 'MLB-SAMPLE-PbP'!$AA$3:INDEX('MLB-SAMPLE-PbP'!$AA:$AA,pbp_LastRow)
Name pbp_Strike2: 'MLB-SAMPLE-PbP'!$AG$3:INDEX('MLB-SAMPLE-PbP'!$AG:$AG,pbp_LastRow)
Name pbp_WP: 'MLB-SAMPLE-PbP'!$AQ$3:INDEX('MLB-SAMPLE-PbP'!$AQ:$AQ,pbp_LastRow)

Sheet MLB-SAMPLE-PbP
A1: GAME INFORMATION | D1: INNING & SCORES | G1: BATTING TEAM | N1: PITCHING TEAM | Z1: PITCH by PITCH | AB1: BALLS & STRIKES | AI1: PLAY
A2: BIGDATABALL DATASET | B2: GAME ID | C2: DATE | D2: INNING | E2: ROAD SCORE | F2: HOME SCORE | G2: BATTING TEAM | H2: BATTER | I2: BATTER MLB-ID | J2: BATTER HAND | K2: RUNNERS ON BASE 1B | L2: RUNNERS ON BASE 2B | M2: RUNNERS ON BASE 3B | N2: PITCHING TEAM | O2: PITCHER | P2: PITCHER MLB-ID | Q2: PITCHER HAND | R2: C | S2: 1B | T2: 2B | U2: 3B | V2: SS | W2: LF | X2: CF | Y2: RF | Z2: PITCHING SEQUENCE LENGTH | AA2: PITCH by PITCH S: Strike; Strike called; Strike swinging | B: Ball, called ball IN: In play | F: Foul; Foul ball on pitchout | FT: Foul tip; Foul tip on bunt | FB: Foul bunt IB: Intentional ball | HB: Hit batter | MB: Missed bunt attempt | NP: No pitch PO: Pitchout | POS: Swinging on pitchout | N-A: Unknown, Missed pitch | POF Pickoff thrown to 1B/2B/3B | AB2: BALLS | AF2: STRIKES | AI2: HIT TYPE | AJ2: PLAY TYPE | AK2: RUNS | AL2: OUTS | AM2: STOLEN BASES | AN2: CAUGHT STEALING | AO2: DEFENSIVE INDIFFERENCE | AP2: PASSED BALL | AQ2: WILD PITCH | AR2: DESCRIPTION
A3: MLB 2025 Postseason | B3: 45962-LAD@TOR-1 | C3: 45962 | D3: 1T | E3: 0 | F3: 0 | G3: Los Angeles Dodgers | H3: Shohei Ohtani | I3: 660271 | J3: L | N3: Toronto Blue Jays | O3: Max Scherzer | P3: 453286 | Q3: R | R3: Alejandro Kirk | S3: Vladimir Guerrero Jr. | T3: Bo Bichette | U3: Ernie Clement | V3: Andres Gimenez | W3: Nathan Lukes | X3: Daulton Varsho | Y3: Addison Barger | Z3: 4 | AA3: B/B/F/IN | AB3: • | AC3: • | AF3: • | AI3: LINE DRIVE | AJ3: SINGLE | AR3: Single to CF
A4: MLB 2025 Postseason | B4: 45962-LAD@TOR-1 | C4: 45962 | D4: 1T | E4: 0 | F4: 0 | G4: Los Angeles Dodgers | H4: Will Smith | I4: 669257 | J4: R | K4: Shohei Ohtani | N4: Toronto Blue Jays | O4: Max Scherzer | P4: 453286 | Q4: R | R4: Alejandro Kirk | S4: Vladimir Guerrero Jr. | T4: Bo Bichette | U4: Ernie Clement | V4: Andres Gimenez | W4: Nathan Lukes | X4: Daulton Varsho | Y4: Addison Barger | Z4: 3 | AA4: S/F/IN | AF4: • | AG4: • | AJ4: GROUNDOUT | AL4: 1 | AR4: Will Smith grounded out, 1B-P. S. Ohtani to 2B
A5: MLB 2025 Postseason | B5: 45962-LAD@TOR-1 | C5: 45962 | D5: 1T | E5: 0 | F5: 0 | G5: Los Angeles Dodgers | H5: Freddie Freeman | I5: 518692 | J5: L | L5: Shohei Ohtani | N5: Toronto Blue Jays | O5: Max Scherzer | P5: 453286 | Q5: R | R5: Alejandro Kirk | S5: Vladimir Guerrero Jr. | T5: Bo Bichette | U5: Ernie Clement | V5: Andres Gimenez | W5: Nathan Lukes | X5: Daulton Varsho | Y5: Addison Barger | Z5: 1 | AA5: IN | AI5: FLY BALL | AJ5: FLYOUT | AL5: 1 | AR5: Freddie Freeman flied out to CF. S. Ohtani to 3B
A6: MLB 2025 Postseason | B6: 45962-LAD@TOR-1 | C6: 45962 | D6: 1T | E6: 0 | F6: 0 | G6: Los Angeles Dodgers | H6: Mookie Betts | I6: 605141 | J6: R | M6: Shohei Ohtani | N6: Toronto Blue Jays | O6: Max Scherzer | P6: 453286 | Q6: R | R6: Alejandro Kirk | S6: Vladimir Guerrero Jr. | T6: Bo Bichette | U6: Ernie Clement | V6: Andres Gimenez | W6: Nathan Lukes | X6: Daulton Varsho | Y6: Addison Barger | Z6: 2 | AA6: B/IN | AB6: • | AJ6: GROUNDOUT | AL6: 1 | AR6: Mookie Betts grounded out, SS-1B
A7: MLB 2025 Postseason | B7: 45962-LAD@TOR-1 | C7: 45962 | D7: 1B | E7: 0 | F7: 0 | G7: Toronto Blue Jays | H7: George Springer | I7: 543807 | J7: R | N7: Los Angeles Dodgers | O7: Shohei Ohtani | P7: 660271 | Q7: R | R7: Will Smith | S7: Freddie Freeman | T7: Miguel Rojas | U7: Max Muncy | V7: Mookie Betts | W7: Enrique Hernandez | X7: Tommy Edman | Y7: Teoscar Hernandez | Z7: 5 | AA7: B/B/B/S/IN | AB7: • | AC7: • | AD7: • | AF7: • | AI7: LINE DRIVE | AJ7: SINGLE | AR7: Single to LF
A8: MLB 2025 Postseason | B8: 45962-LAD@TOR-1 | C8: 45962 | D8: 1B | E8: 0 | F8: 0 | G8: Toronto Blue Jays | H8: Nathan Lukes | I8: 664770 | J8: L | K8: George Springer | N8: Los Angeles Dodgers | O8: Shohei Ohtani | P8: 660271 | Q8: R | R8: Will Smith | S8: Freddie Freeman | T8: Miguel Rojas | U8: Max Muncy | V8: Mookie Betts | W8: Enrique Hernandez | X8: Tommy Edman | Y8: Teoscar Hernandez | Z8: 7 | AA8: B/S/S/F/B/F/S | AB8: • | AC8: • | AF8: • | AG8: • | AH8: • | AJ8: STRIKEOUT | AL8: 1 | AR8: Nathan Lukes struck out [swinging].
A9: MLB 2025 Postseason | B9: 45962-LAD@TOR-1 | C9: 45962 | D9: 1B | E9: 0 | F9: 0 | G9: Toronto Blue Jays | H9: Vladimir Guerrero Jr. | I9: 665489 | J9: R | K9: George Springer | N9: Los Angeles Dodgers | O9: Shohei Ohtani | P9: 660271 | Q9: R | R9: Will Smith | S9: Freddie Freeman | T9: Miguel Rojas | U9: Max Muncy | V9: Mookie Betts | W9: Enrique Hernandez | X9: Tommy Edman | Y9: Teoscar Hernandez | Z9: 6 | AA9: B/B/S/B/F/S | AB9: • | AC9: • | AD9: • | AF9: • | AG9: • | AH9: • | AJ9: DOUBLE PLAY | AL9: 2 | AN9: 1 | AR9: Double Play: Vladimir Guerrero Jr. struck out [looking]., G. Springer was caught stealing. 2B
A10: MLB 2025 Postseason | B10: 45962-LAD@TOR-1 | C10: 45962 | D10: 2T | E10: 0 | F10: 0 | G10: Los Angeles Dodgers | H10: Max Muncy | I10: 571970 | J10: L | N10: Toronto Blue Jays | O10: Max Scherzer | P10: 453286 | Q10: R | R10: Alejandro Kirk | S10: Vladimir Guerrero Jr. | T10: Bo Bichette | U10: Ernie Clement | V10: Andres Gimenez | W10: Nathan Lukes | X10: Daulton Varsho | Y10: Addison Barger | Z10: 5 | AA10: S/B/B/F/S | AB10: • | AC10: • | AF10: • | AG10: • | AH10: • | AJ10: STRIKEOUT | AL10: 1 | AR10: Max Muncy struck out [swinging].
A11: MLB 2025 Postseason | B11: 45962-LAD@TOR-1 | C11: 45962 | D11: 2T | E11: 0 | F11: 0 | G11: Los Angeles Dodgers | H11: Teoscar Hernandez | I11: 606192 | J11: R | N11: Toronto Blue Jays | O11: Max Scherzer | P11: 453286 | Q11: R | R11: Alejandro Kirk | S11: Vladimir Guerrero Jr. | T11: Bo Bichette | U11: Ernie Clement | V11: Andres Gimenez | W11: Nathan Lukes | X11: Daulton Varsho | Y11: Addison Barger | Z11: 2 | AA11: S/IN | AF11: • | AI11: FLY BALL | AJ11: FLYOUT | AL11: 1 | AR11: Teoscar Hernandez flied out to RF
A12: MLB 2025 Postseason | B12: 45962-LAD@TOR-1 | C12: 45962 | D12: 2T | E12: 0 | F12: 0 | G12: Los Angeles Dodgers | H12: Tommy Edman | I12: 669242 | J12: S | N12: Toronto Blue Jays | O12: Max Scherzer | P12: 453286 | Q12: R | R12: Alejandro Kirk | S12: Vladimir Guerrero Jr. | T12: Bo Bichette | U12: Ernie Clement | V12: Andres Gimenez | W12: Nathan Lukes | X12: Daulton Varsho | Y12: Addison Barger | Z12: 3 | AA12: B/B/IN | AB12: • | AC12: • | AI12: FLY BALL | AJ12: FLYOUT | AL12: 1 | AR12: Tommy Edman flied out to RF
A13: MLB 2025 Postseason | B13: 45962-LAD@TOR-1 | C13: 45962 | D13: 2B | E13: 0 | F13: 0 | G13: Toronto Blue Jays | H13: Bo Bichette | I13: 666182 | J13: R | N13: Los Angeles Dodgers | O13: Shohei Ohtani | P13: 660271 | Q13: R | R13: Will Smith | S13: Freddie Freeman | T13: Miguel Rojas | U13: Max Muncy | V13: Mookie Betts | W13: Enrique Hernandez | X13: Tommy Edman | Y13: Teoscar Hernandez | Z13: 5 | AA13: B/B/S/B/B | AB13: • | AC13: • | AD13: • | AE13: • | AF13: • | AJ13: WALK | AR13: Bo Bichette walked.
A14: MLB 2025 Postseason | B14: 45962-LAD@TOR-1 | C14: 45962 | D14: 2B | E14: 0 | F14: 0 | G14: Toronto Blue Jays | H14: Addison Barger | I14: 680718 | J14: L | K14: Bo Bichette | N14: Los Angeles Dodgers | O14: Shohei Ohtani | P14: 660271 | Q14: R | R14: Will Smith | S14: Freddie Freeman | T14: Miguel Rojas | U14: Max Muncy | V14: Mookie Betts | W14: Enrique Hernandez | X14: Tommy Edman | Y14: Teoscar Hernandez | Z14: 6 | AA14: S/B/B/S/B/IN | AB14: • | AC14: • | AD14: • | AF14: • | AG14: • | AI14: LINE DRIVE | AJ14: SINGLE | AR14: Single to RF. B. Bichette to 2B
A15: MLB 2025 Postseason | B15: 45962-LAD@TOR-1 | C15: 45962 | D15: 2B | E15: 0 | F15: 0 | G15: Toronto Blue Jays | H15: Alejandro Kirk | I15: 672386 | J15: R | K15: Addison Barger | L15: Bo Bichette | N15: Los Angeles Dodgers | O15: Shohei Ohtani | P15: 660271 | Q15: R | R15: Will Smith | S15: Freddie Freeman | T15: Miguel Rojas | U15: Max Muncy | V15: Mookie Betts | W15: Enrique Hernandez | X15: Tommy Edman | Y15: Teoscar Hernandez | Z15: 2 | AA15: S/IN | AF15: • | AI15: POP-UP | AJ15: POP OUT | AL15: 1 | AR15: Alejandro Kirk out to 1B
A16: MLB 2025 Postseason | B16: 45962-LAD@TOR-1 | C16: 45962 | D16: 2B | E16: 0 | F16: 0 | G16: Toronto Blue Jays | H16: Daulton Varsho | I16: 662139 | J16: L | K16: Addison Barger | L16: Bo Bichette | N16: Los Angeles Dodgers | O16: Shohei Ohtani | P16: 660271 | Q16: R | R16: Will Smith | S16: Freddie Freeman | T16: Miguel Rojas | U16: Max Muncy | V16: Mookie Betts | W16: Enrique Hernandez | X16: Tommy Edman | Y16: Teoscar Hernandez | Z16: 5 | AA16: S/B/S/B/IN | AB16: • | AC16: • | AF16: • | AG16: • | AI16: FLY BALL | AJ16: FLYOUT | AL16: 1 | AR16: Daulton Varsho flied out to RF
A17: MLB 2025 Postseason | B17: 45962-LAD@TOR-1 | C17: 45962 | D17: 2B | E17: 0 | F17: 0 | G17: Toronto Blue Jays | H17: Ernie Clement | I17: 676391 | J17: R | K17: Addison Barger | L17: Bo Bichette | N17: Los Angeles Dodgers | O17: Shohei Ohtani | P17: 660271 | Q17: R | R17: Will Smith | S17: Freddie Freeman | T17: Miguel Rojas | U17: Max Muncy | V17: Mookie Betts | W17: Enrique Hernandez | X17: Tommy Edman | Y17: Teoscar Hernandez | Z17: 2 | AA17: F/IN | AF17: • | AI17: LINE DRIVE | AJ17: SINGLE | AR17: Single to RF. B. Bichette to 3B. A. Barger to 2B
A18: MLB 2025 Postseason | B18: 45962-LAD@TOR-1 | C18: 45962 | D18: 2B | E18: 0 | F18: 0 | G18: Toronto Blue Jays | H18: Andres Gimenez | I18: 665926 | J18: L | K18: Ernie Clement | L18: Addison Barger | M18: Bo Bichette | N18: Los Angeles Dodgers | O18: Shohei Ohtani | P18: 660271 | Q18: R | R18: Will Smith | S18: Freddie Freeman | T18: Miguel Rojas | U18: Max Muncy | V18: Mookie Betts | W18: Enrique Hernandez | X18: Tommy Edman | Y18: Teoscar Hernandez | Z18: 5 | AA18: B/S/S/F/S | AB18: • | AF18: • | AG18: • | AH18: • | AJ18: STRIKEOUT | AL18: 1 | AR18: Andres Gimenez struck out [swinging].
A19: MLB 2025 Postseason | B19: 45962-LAD@TOR-1 | C19: 45962 | D19: 3T | E19: 0 | F19: 0 | G19: Los Angeles Dodgers | H19: Enrique Hernandez | I19: 571771 | J19: R | N19: Toronto Blue Jays | O19: Max Scherzer | P19: 453286 | Q19: R | R19: Alejandro Kirk | S19: Vladimir Guerrero Jr. | T19: Bo Bichette | U19: Ernie Clement | V19: Andres Gimenez | W19: Nathan Lukes | X19: Daulton Varsho | Y19: Addison Barger | Z19: 3 | AA19: S/B/IN | AB19: • | AF19: • | AI19: FLY BALL | AJ19: FLYOUT | AL19: 1 | AR19: Enrique Hernandez flied out to CF
A20: MLB 2025 Postseason | B20: 45962-LAD@TOR-1 | C20: 45962 | D20: 3T | E20: 0 | F20: 0 | G20: Los Angeles Dodgers | H20: Miguel Rojas | I20: 500743 | J20: R | N20: Toronto Blue Jays | O20: Max Scherzer | P20: 453286 | Q20: R | R20: Alejandro Kirk | S20: Vladimir Guerrero Jr. | T20: Bo Bichette | U20: Ernie Clement | V20: Andres Gimenez | W20: Nathan Lukes | X20: Daulton Varsho | Y20: Addison Barger | Z20: 4 | AA20: S/F/B/S | AB20: • | AF20: • | AG20: • | AH20: • | AJ20: STRIKEOUT | AL20: 1 | AR20: Miguel Rojas struck out [swinging].
A21: MLB 2025 Postseason | B21: 45962-LAD@TOR-1 | C21: 45962 | D21: 3T | E21: 0 | F21: 0 | G21: Los Angeles Dodgers | H21: Shohei Ohtani | I21: 660271 | J21: L | N21: Toronto Blue Jays | O21: Max Scherzer | P21: 453286 | Q21: R | R21: Alejandro Kirk | S21: Vladimir Guerrero Jr. | T21: Bo Bichette | U21: Ernie Clement | V21: Andres Gimenez | W21: Nathan Lukes | X21: Daulton Varsho | Y21: Addison Barger | Z21: 1 | AA21: IN | AJ21: LINEOUT | AL21: 1 | AR21: Shohei Ohtani lined out to LF
A22: MLB 2025 Postseason | B22: 45962-LAD@TOR-1 | C22: 45962 | D22: 3B | E22: 0 | F22: 0 | G22: Toronto Blue Jays | H22: George Springer | I22: 543807 | J22: R | N22: Los Angeles Dodgers | O22: Shohei Ohtani | P22: 660271 | Q22: R | R22: Will Smith | S22: Freddie Freeman | T22: Miguel Rojas | U22: Max Muncy | V22: Mookie Betts | W22: Enrique Hernandez | X22: Tommy Edman | Y22: Teoscar Hernandez | Z22: 5 | AA22: F/S/F/B/IN | AB22: • | AF22: • | AG22: • | AI22: LINE DRIVE | AJ22: SINGLE | AR22: Single to LF
A23: MLB 2025 Postseason | B23: 45962-LAD@TOR-1 | C23: 45962 | D23: 3B | E23: 0 | F23: 0 | G23: Toronto Blue Jays | H23: Nathan Lukes | I23: 664770 | J23: L | K23: George Springer | N23: Los Angeles Dodgers | O23: Shohei Ohtani | P23: 660271 | Q23: R | R23: Will Smith | S23: Freddie Freeman | T23: Miguel Rojas | U23: Max Muncy | V23: Mookie Betts | W23: Enrique Hernandez | X23: Tommy Edman | Y23: Teoscar Hernandez | Z23: 1 | AA23: IN | AJ23: SAC BUNT | AL23: 1 | AR23: Bunt Nathan Lukes grounded out, P-1B/Sacrifice. G. Springer to 2B
A24: MLB 2025 Postseason | B24: 45962-LAD@TOR-1 | C24: 45962 | D24: 3B | E24: 0 | F24: 0 | G24: Toronto Blue Jays | H24: Vladimir Guerrero Jr. | I24: 665489 | J24: R | L24: George Springer | N24: Los Angeles Dodgers | O24: Shohei Ohtani | P24: 660271 | Q24: R | R24: Will Smith | S24: Freddie Freeman | T24: Miguel Rojas | U24: Max Muncy | V24: Mookie Betts | W24: Enrique Hernandez | X24: Tommy Edman | Y24: Teoscar Hernandez | Z24: 1 | AA24: B | AQ24: 1 | AR24: Wild Pitch. G. Springer to 3B
A25: MLB 2025 Postseason | B25: 45962-LAD@TOR-1 | C25: 45962 | D25: 3B | E25: 0 | F25: 0 | G25: Toronto Blue Jays | H25: Vladimir Guerrero Jr. | I25: 665489 | J25: R | M25: George Springer | N25: Los Angeles Dodgers | O25: Shohei Ohtani | P25: 660271 | Q25: R | R25: Will Smith | S25: Freddie Freeman | T25: Miguel Rojas | U25: Max Muncy | V25: Mookie Betts | W25: Enrique Hernandez | X25: Tommy Edman | Y25: Teoscar Hernandez | Z25: 1 | AA25: B/B/B/B | AJ25: INTENT WALK | AR25: Vladimir Guerrero Jr. was intentionally walked.
A26: MLB 2025 Postseason | B26: 45962-LAD@TOR-1 | C26: 45962 | D26: 3B | E26: 0 | F26: 0 | G26: Toronto Blue Jays | H26: Bo Bichette | I26: 666182 | J26: R | K26: Vladimir Guerrero Jr. | M26: George Springer | N26: Los Angeles Dodgers | O26: Shohei Ohtani | P26: 660271 | Q26: R | R26: Will Smith | S26: Freddie Freeman | T26: Miguel Rojas | U26: Max Muncy | V26: Mookie Betts | W26: Enrique Hernandez | X26: Tommy Edman | Y26: Teoscar Hernandez | Z26: 1 | AA26: IN | AI26: FLY BALL | AJ26: HOME RUN | AK26: 3 | AR26: Home Run. G. Springer scored.. V. Guerrero scored.
A27: MLB 2025 Postseason | B27: 45962-LAD@TOR-1 | C27: 45962 | D27: 3B | E27: 0 | F27: 3 | G27: Toronto Blue Jays | H27: Addison Barger | I27: 680718 | J27: L | N27: Los Angeles Dodgers | O27: Justin Wrobleski | P27: 680736 | Q27: L | R27: Will Smith | S27: Freddie Freeman | T27: Miguel Rojas | U27: Max Muncy | V27: Mookie Betts | W27: Enrique Hernandez | X27: Tommy Edman | Y27: Teoscar Hernandez | Z27: 3 | AA27: S/F/IN | AF27: • | AG27: • | AI27: LINE DRIVE | AJ27: SINGLE | AR27: Single to CF
A28: MLB 2025 Postseason | B28: 45962-LAD@TOR-1 | C28: 45962 | D28: 3B | E28: 0 | F28: 3 | G28: Toronto Blue Jays | H28: Alejandro Kirk | I28: 672386 | J28: R | K28: Addison Barger | N28: Los Angeles Dodgers | O28: Justin Wrobleski | P28: 680736 | Q28: L | R28: Will Smith | S28: Freddie Freeman | T28: Miguel Rojas | U28: Max Muncy | V28: Mookie Betts | W28: Enrique Hernandez | X28: Tommy Edman | Y28: Teoscar Hernandez | Z28: 2 | AA28: S/IN | AF28: • | AJ28: LINEOUT | AL28: 1 | AR28: Alejandro Kirk lined out to CF
A29: MLB 2025 Postseason | B29: 45962-LAD@TOR-1 | C29: 45962 | D29: 3B | E29: 0 | F29: 3 | G29: Toronto Blue Jays | H29: Daulton Varsho | I29: 662139 | J29: L | K29: Addison Barger | N29: Los Angeles Dodgers | O29: Justin Wrobleski | P29: 680736 | Q29: L | R29: Will Smith | S29: Freddie Freeman | T29: Miguel Rojas | U29: Max Muncy | V29: Mookie Betts | W29: Enrique Hernandez | X29: Tommy Edman | Y29: Teoscar Hernandez | Z29: 4 | AA29: B/F/S/S | AB29: • | AF29: • | AG29: • | AH29: • | AJ29: STRIKEOUT | AL29: 1 | AR29: Daulton Varsho struck out [swinging].
A30: MLB 2025 Postseason | B30: 45962-LAD@TOR-1 | C30: 45962 | D30: 4T | E30: 0 | F30: 3 | G30: Los Angeles Dodgers | H30: Will Smith | I30: 669257 | J30: R | N30: Toronto Blue Jays | O30: Max Scherzer | P30: 453286 | Q30: R | R30: Alejandro Kirk | S30: Vladimir Guerrero Jr. | T30: Bo Bichette | U30: Ernie Clement | V30: Andres Gimenez | W30: Nathan Lukes | X30: Daulton Varsho | Y30: Addison Barger | Z30: 1 | AA30: IN | AI30: FLY BALL | AJ30: DOUBLE | AR30: Double to CF
A31: MLB 2025 Postseason | B31: 45962-LAD@TOR-1 | C31: 45962 | D31: 4T | E31: 0 | F31: 3 | G31: Los Angeles Dodgers | H31: Freddie Freeman | I31: 518692 | J31: L | L31: Will Smith | N31: Toronto Blue Jays | O31: Max Scherzer | P31: 453286 | Q31: R | R31: Alejandro Kirk | S31: Vladimir Guerrero Jr. | T31: Bo Bichette | U31: Ernie Clement | V31: Andres Gimenez | W31: Nathan Lukes | X31: Daulton Varsho | Y31: Addison Barger | Z31: 3 | AA31: S/B/IN | AB31: • | AF31: • | AI31: LINE DRIVE | AJ31: SINGLE | AR31: Single to RF. W. Smith to 3B
A32: MLB 2025 Postseason | B32: 45962-LAD@TOR-1 | C32: 45962 | D32: 4T | E32: 0 | F32: 3 | G32: Los Angeles Dodgers | H32: Mookie Betts | I32: 605141 | J32: R | K32: Freddie Freeman | M32: Will Smith | N32: Toronto Blue Jays | O32: Max Scherzer | P32: 453286 | Q32: R | R32: Alejandro Kirk | S32: Vladimir Guerrero Jr. | T32: Bo Bichette | U32: Ernie Clement | V32: Andres Gimenez | W32: Nathan Lukes | X32: Daulton Varsho | Y32: Addison Barger | Z32: 3 | AA32: B/S/IN | AB32: • | AF32: • | AI32: FLY BALL | AJ32: FLYOUT | AL32: 1 | AR32: Mookie Betts flied out to RF
A33: MLB 2025 Postseason | B33: 45962-LAD@TOR-1 | C33: 45962 | D33: 4T | E33: 0 | F33: 3 | G33: Los Angeles Dodgers | H33: Max Muncy | I33: 571970 | J33: L | K33: Freddie Freeman | M33: Will Smith | N33: Toronto Blue Jays | O33: Max Scherzer | P33: 453286 | Q33: R | R33: Alejandro Kirk | S33: Vladimir Guerrero Jr. | T33: Bo Bichette | U33: Ernie Clement | V33: Andres Gimenez | W33: Nathan Lukes | X33: Daulton Varsho | Y33: Addison Barger | Z33: 7 | AA33: F/B/B/B/F/F/B | AB33: • | AC33: • | AD33: • | AE33: • | AF33: • | AG33: • | AJ33: WALK | AR33: Max Muncy walked.. F. Freeman to 2B
A34: MLB 2025 Postseason | B34: 45962-LAD@TOR-1 | C34: 45962 | D34: 4T | E34: 0 | F34: 3 | G34: Los Angeles Dodgers | H34: Teoscar Hernandez | I34: 606192 | J34: R | K34: Max Muncy | L34: Freddie Freeman | M34: Will Smith | N34: Toronto Blue Jays | O34: Max Scherzer | P34: 453286 | Q34: R | R34: Alejandro Kirk | S34: Vladimir Guerrero Jr. | T34: Bo Bichette | U34: Ernie Clement | V34: Andres Gimenez | W34: Nathan Lukes | X34: Daulton Varsho | Y34: Addison Barger | Z34: 2 | AA34: B/IN | AB34: • | AJ34: SAC FLY | AK34: 1 | AL34: 1 | AR34: Teoscar Hernandez lined out to CF on a sacrifice fly.. W. Smith scored.
A35: MLB 2025 Postseason | B35: 45962-LAD@TOR-1 | C35: 45962 | D35: 4T | E35: 1 | F35: 3 | G35: Los Angeles Dodgers | H35: Tommy Edman | I35: 669242 | J35: S | K35: Max Muncy | L35: Freddie Freeman | N35: Toronto Blue Jays | O35: Max Scherzer | P35: 453286 | Q35: R | R35: Alejandro Kirk | S35: Vladimir Guerrero Jr. | T35: Bo Bichette | U35: Ernie Clement | V35: Andres Gimenez | W35: Nathan Lukes | X35: Daulton Varsho | Y35: Addison Barger | Z35: 3 | AA35: B/B/IN | AB35: • | AC35: • | AI35: POP-UP | AJ35: POP OUT | AL35: 1 | AR35: Tommy Edman out to 1B
A36: MLB 2025 Postseason | B36: 45962-LAD@TOR-1 | C36: 45962 | D36: 4B | E36: 1 | F36: 3 | G36: Toronto Blue Jays | H36: Ernie Clement | I36: 676391 | J36: R | N36: Los Angeles Dodgers | O36: Justin Wrobleski | P36: 680736 | Q36: L | R36: Will Smith | S36: Freddie Freeman | T36: Miguel Rojas | U36: Max Muncy | V36: Mookie Betts | W36: Enrique Hernandez | X36: Tommy Edman | Y36: Teoscar Hernandez | Z36: 1 | AA36: IN | AJ36: GROUNDOUT | AL36: 1 | AR36: Ernie Clement grounded out, SS-1B
A37: MLB 2025 Postseason | B37: 45962-LAD@TOR-1 | C37: 45962 | D37: 4B | E37: 1 | F37: 3 | G37: Toronto Blue Jays | H37: Andres Gimenez | I37: 665926 | J37: L | N37: Los Angeles Dodgers | O37: Justin Wrobleski | P37: 680736 | Q37: L | R37: Will Smith | S37: Freddie Freeman | T37: Miguel Rojas | U37: Max Muncy | V37: Mookie Betts | W37: Enrique Hernandez | X37: Tommy Edman | Y37: Teoscar Hernandez | Z37: 5 | AA37: B/S/F/B/HB | AB37: • | AC37: • | AF37: • | AG37: • | AJ37: HIT BY PITCH | AR37: Andres Gimenez was hit by a pitch.
A38: MLB 2025 Postseason | B38: 45962-LAD@TOR-1 | C38: 45962 | D38: 4B | E38: 1 | F38: 3 | G38: Toronto Blue Jays | H38: George Springer | I38: 543807 | J38: R | K38: Andres Gimenez | N38: Los Angeles Dodgers | O38: Justin Wrobleski | P38: 680736 | Q38: L | R38: Will Smith | S38: Freddie Freeman | T38: Miguel Rojas | U38: Max Muncy | V38: Mookie Betts | W38: Enrique Hernandez | X38: Tommy Edman | Y38: Teoscar Hernandez | Z38: 2 | AA38: B/IN | AB38: • | AI38: LINE DRIVE | AJ38: SINGLE | AR38: Single to P. A. Giménez to 2B
A39: MLB 2025 Postseason | B39: 45962-LAD@TOR-1 | C39: 45962 | D39: 4B | E39: 1 | F39: 3 | G39: Toronto Blue Jays | H39: Nathan Lukes | I39: 664770 | J39: L | K39: George Springer | L39: Andres Gimenez | N39: Los Angeles Dodgers | O39: Justin Wrobleski | P39: 680736 | Q39: L | R39: Will Smith | S39: Freddie Freeman | T39: Miguel Rojas | U39: Max Muncy | V39: Mookie Betts | W39: Enrique Hernandez | X39: Tommy Edman | Y39: Teoscar Hernandez | Z39: 4 | AA39: F/S/B/S | AB39: • | AF39: • | AG39: • | AH39: • | AJ39: STRIKEOUT | AL39: 1 | AR39: Nathan Lukes struck out [swinging].
A40: MLB 2025 Postseason | B40: 45962-LAD@TOR-1 | C40: 45962 | D40: 4B | E40: 1 | F40: 3 | G40: Toronto Blue Jays | H40: Vladimir Guerrero Jr. | I40: 665489 | J40: R | K40: George Springer | L40: Andres Gimenez | N40: Los Angeles Dodgers | O40: Tyler Glasnow | P40: 607192 | Q40: R | R40: Will Smith | S40: Freddie Freeman | T40: Miguel Rojas | U40: Max Muncy | V40: Mookie Betts | W40: Enrique Hernandez | X40: Tommy Edman | Y40: Teoscar Hernandez | Z40: 5 | AA40: B/S/B/B/IN | AB40: • | AC40: • | AD40: • | AF40: • | AJ40: LINEOUT | AL40: 1 | AR40: Vladimir Guerrero Jr. lined out to CF
...

Sheet Analytics Dashboard
B2: Offensive & Defensive Analytics Dashboard
B3: Built on the 'MLB-SAMPLE-PbP' tab. All figures are live formulas; add rows to the data tab and everything updates.
B5: Data coverage
B6: Event rows | C6: =Lists!C8 -> 101
B7: Plate appearances | C7: =Lists!C7 -> 99
B8: Games | C8: =SUMPRODUCT((pbp_GameID<>pbp_GameIDPrev)*1) -> 1
B9: Unmapped play types (should be 0) | C9: =Lists!C9 -> 0
B11: Team head-to-head (first two teams in data)
B12: Metric | C12: Team 1 | D12: Team 2 | E12: Edge
B13: Team | C13: ='Team Offense'!B6 -> Los Angeles Dodgers | D13: ='Team Offense'!B7 -> Toronto Blue Jays
B14: Runs | C14: =IFERROR(INDEX('Team Offense'!$F$6:$F$35,MATCH(C$13,'Team Offense'!$B$6:$B$35,0)),"") -> 5 | D14: =IFERROR(INDEX('Team Offense'!$F$6:$F$35,MATCH(D$13,'Team Offense'!$B$6:$B$35,0)),"") -> 4 | E14: =IF(OR(C14="",D14=""),"",IF(C14=D14,"Even",IF(C14>D14,$C$13,$D$13))) -> Los Angeles Dodgers
B15: OPS | C15: =IFERROR(INDEX('Team Offense'!$Y$6:$Y$35,MATCH(C$13,'Team Offense'!$B$6:$B$35,0)),"") -> 0.84552846 | D15: =IFERROR(INDEX('Team Offense'!$Y$6:$Y$35,MATCH(D$13,'Team Offense'!$B$6:$B$35,0)),"") -> 0.87327954 | E15: =IF(OR(C15="",D15=""),"",IF(C15=D15,"Even",IF(C15>D15,$C$13,$D$13))) -> Toronto Blue Jays
B16: AVG | C16: =IFERROR(INDEX('Team Offense'!$V$6:$V$35,MATCH(C$13,'Team Offense'!$B$6:$B$35,0)),"") -> 0.26829268 | D16: =IFERROR(INDEX('Team Offense'!$V$6:$V$35,MATCH(D$13,'Team Offense'!$B$6:$B$35,0)),"") -> 0.3255814 | E16: =IF(OR(C16="",D16=""),"",IF(C16=D16,"Even",IF(C16>D16,$C$13,$D$13))) -> Toronto Blue Jays
B17: ISO (power) | C17: =IFERROR(INDEX('Team Offense'!$Z$6:$Z$35,MATCH(C$13,'Team Offense'!$B$6:$B$35,0)),"") -> 0.24390244 | D17: =IFERROR(INDEX('Team Offense'!$Z$6:$Z$35,MATCH(D$13,'Team Offense'!$B$6:$B$35,0)),"") -> 0.13953488 | E17: =IF(OR(C17="",D17=""),"",IF(C17=D17,"Even",IF(C17>D17,$C$13,$D$13))) -> Los Angeles Dodgers
B18: BB/K | C18: =IFERROR(INDEX('Team Offense'!$AD$6:$AD$35,MATCH(C$13,'Team Offense'!$B$6:$B$35,0)),"") -> 1 | D18: =IFERROR(INDEX('Team Offense'!$AD$6:$AD$35,MATCH(D$13,'Team Offense'!$B$6:$B$35,0)),"") -> 0.33333333 | E18: =IF(OR(C18="",D18=""),"",IF(C18=D18,"Even",IF(C18>D18,$C$13,$D$13))) -> Los Angeles Dodgers
B19: Pitches per PA (patience) | C19: =IFERROR(INDEX('Team Offense'!$AE$6:$AE$35,MATCH(C$13,'Team Offense'!$B$6:$B$35,0)),"") -> 3.5833333 | D19: =IFERROR(INDEX('Team Offense'!$AE$6:$AE$35,MATCH(D$13,'Team Offense'!$B$6:$B$35,0)),"") -> 3.7647059 | E19: =IF(OR(C19="",D19=""),"",IF(C19=D19,"Even",IF(C19>D19,$C$13,$D$13))) -> Toronto Blue Jays
B20: Strike % (pitching) | C20: =IFERROR(INDEX('Team Pitching & Defense'!$P$6:$P$35,MATCH(C$13,'Team Pitching & Defense'!$B$6:$B$35,0)),"") -> 0.61538462 | D20: =IFERROR(INDEX('Team Pitching & Defense'!$P$6:$P$35,MATCH(D$13,'Team Pitching & Defense'!$B$6:$B$35,0)),"") -> 0.60465116 | E20: =IF(OR(C20="",D20=""),"",IF(C20=D20,"Even",IF(C20>D20,$C$13,$D$13))) -> Los Angeles Dodgers
B21: First-pitch strike % | C21: =IFERROR(INDEX('Team Pitching & Defense'!$Q$6:$Q$35,MATCH(C$13,'Team Pitching & Defense'!$B$6:$B$35,0)),"") -> 0.54901961 | D21: =IFERROR(INDEX('Team Pitching & Defense'!$Q$6:$Q$35,MATCH(D$13,'Team Pitching & Defense'!$B$6:$B$35,0)),"") -> 0.625 | E21: =IF(OR(C21="",D21=""),"",IF(C21=D21,"Even",IF(C21>D21,$C$13,$D$13))) -> Toronto Blue Jays
B22: K-BB% (pitching) | C22: =IFERROR(INDEX('Team Pitching & Defense'!$T$6:$T$35,MATCH(C$13,'Team Pitching & Defense'!$B$6:$B$35,0)),"") -> 0.15686275 | D22: =IFERROR(INDEX('Team Pitching & Defense'!$T$6:$T$35,MATCH(D$13,'Team Pitching & Defense'!$B$6:$B$35,0)),"") -> 0 | E22: =IF(OR(C22="",D22=""),"",IF(C22=D22,"Even",IF(C22>D22,$C$13,$D$13))) -> Los Angeles Dodgers
B23: FIP | C23: =IFERROR(INDEX('Team Pitching & Defense'!$V$6:$V$35,MATCH(C$13,'Team Pitching & Defense'!$B$6:$B$35,0)),"") -> 3.7363636 | D23: =IFERROR(INDEX('Team Pitching & Defense'!$V$6:$V$35,MATCH(D$13,'Team Pitching & Defense'!$B$6:$B$35,0)),"") -> 7.1 | E23: =IF(OR(C23="",D23=""),"",IF(C23=D23,"Even",IF(C23<D23,$C$13,$D$13))) -> Los Angeles Dodgers
B24: WHIP | C24: =IFERROR(INDEX('Team Pitching & Defense'!$U$6:$U$35,MATCH(C$13,'Team Pitching & Defense'!$B$6:$B$35,0)),"") -> 1.6363636 | D24: =IFERROR(INDEX('Team Pitching & Defense'!$U$6:$U$35,MATCH(D$13,'Team Pitching & Defense'!$B$6:$B$35,0)),"") -> 1.4545455 | E24: =IF(OR(C24="",D24=""),"",IF(C24=D24,"Even",IF(C24<D24,$C$13,$D$13))) -> Toronto Blue Jays
B25: Defensive efficiency (DER) | C25: =IFERROR(INDEX('Team Pitching & Defense'!$Y$6:$Y$35,MATCH(C$13,'Team Pitching & Defense'!$B$6:$B$35,0)),"") -> 0.56666667 | D25: =IFERROR(INDEX('Team Pitching & Defense'!$Y$6:$Y$35,MATCH(D$13,'Team Pitching & Defense'!$B$6:$B$35,0)),"") -> 0.77142857 | E25: =IF(OR(C25="",D25=""),"",IF(C25=D25,"Even",IF(C25>D25,$C$13,$D$13))) -> Toronto Blue Jays
B26: Double plays turned | C26: =IFERROR(INDEX('Team Pitching & Defense'!$AB$6:$AB$35,MATCH(C$13,'Team Pitching & Defense'!$B$6:$B$35,0)),"") -> 2 | D26: =IFERROR(INDEX('Team Pitching & Defense'!$AB$6:$AB$35,MATCH(D$13,'Team Pitching & Defense'!$B$6:$B$35,0)),"") -> 1 | E26: =IF(OR(C26="",D26=""),"",IF(C26=D26,"Even",IF(C26>D26,$C$13,$D$13))) -> Los Angeles Dodgers
B29: Top batters by OPS (min PA on Lists tab) | H29: Top pitchers by FIP (min BF on Lists tab)
B30: Rank | C30: Batter | D30: Team | E30: PA | F30: OPS | H30: Rank | I30: Pitcher | J30: Team | K30: BF | L30: FIP
B31: 1 | C31: =IFERROR(INDEX('Batter Leaders'!$B$6:$B$255,MATCH(B31,'Batter Leaders'!$AA$6:$AA$255,0)),"") -> Max Muncy | D31: =IFERROR(INDEX('Batter Leaders'!$C$6:$C$255,MATCH(C31,'Batter Leaders'!$B$6:$B$255,0)),"") -> Los Angeles Dodgers | E31: =IFERROR(INDEX('Batter Leaders'!$E$6:$E$255,MATCH(C31,'Batter Leaders'!$B$6:$B$255,0)),"") -> 5 | F31: =IFERROR(INDEX('Batter Leaders'!$T$6:$T$255,MATCH(C31,'Batter Leaders'!$B$6:$B$255,0)),"") -> 2.3 | H31: 1 | I31: =IFERROR(INDEX('Pitcher Leaders'!$B$6:$B$255,MATCH(H31,'Pitcher Leaders'!$AA$6:$AA$255,0)),"") -> Emmet Sheehan | J31: =IFERROR(INDEX('Pitcher Leaders'!$C$6:$C$255,MATCH(I31,'Pitcher Leaders'!$B$6:$B$255,0)),"") -> Los Angeles Dodgers | K31: =IFERROR(INDEX('Pitcher Leaders'!$E$6:$E$255,MATCH(I31,'Pitcher Leaders'!$B$6:$B$255,0)),"") -> 5 | L31: =IFERROR(INDEX('Pitcher Leaders'!$X$6:$X$255,MATCH(I31,'Pitcher Leaders'!$B$6:$B$255,0)),"") -> -0.9
B32: 2 | C32: =IFERROR(INDEX('Batter Leaders'!$B$6:$B$255,MATCH(B32,'Batter Leaders'!$AA$6:$AA$255,0)),"") -> Bo Bichette | D32: =IFERROR(INDEX('Batter Leaders'!$C$6:$C$255,MATCH(C32,'Batter Leaders'!$B$6:$B$255,0)),"") -> Toronto Blue Jays | E32: =IFERROR(INDEX('Batter Leaders'!$E$6:$E$255,MATCH(C32,'Batter Leaders'!$B$6:$B$255,0)),"") -> 5 | F32: =IFERROR(INDEX('Batter Leaders'!$T$6:$T$255,MATCH(C32,'Batter Leaders'!$B$6:$B$255,0)),"") -> 1.85 | H32: 2 | I32: =IFERROR(INDEX('Pitcher Leaders'!$B$6:$B$255,MATCH(H32,'Pitcher Leaders'!$AA$6:$AA$255,0)),"") -> Tyler Glasnow | J32: =IFERROR(INDEX('Pitcher Leaders'!$C$6:$C$255,MATCH(I32,'Pitcher Leaders'!$B$6:$B$255,0)),"") -> Los Angeles Dodgers | K32: =IFERROR(INDEX('Pitcher Leaders'!$E$6:$E$255,MATCH(I32,'Pitcher Leaders'!$B$6:$B$255,0)),"") -> 10 | L32: =IFERROR(INDEX('Pitcher Leaders'!$X$6:$X$255,MATCH(I32,'Pitcher Leaders'!$B$6:$B$255,0)),"") -> 1.3857143
B33: 3 | C33: =IFERROR(INDEX('Batter Leaders'!$B$6:$B$255,MATCH(B33,'Batter Leaders'!$AA$6:$AA$255,0)),"") -> Ernie Clement | D33: =IFERROR(INDEX('Batter Leaders'!$C$6:$C$255,MATCH(C33,'Batter Leaders'!$B$6:$B$255,0)),"") -> Toronto Blue Jays | E33: =IFERROR(INDEX('Batter Leaders'!$E$6:$E$255,MATCH(C33,'Batter Leaders'!$B$6:$B$255,0)),"") -> 5 | F33: =IFERROR(INDEX('Batter Leaders'!$T$6:$T$255,MATCH(C33,'Batter Leaders'!$B$6:$B$255,0)),"") -> 1.4 | H33: 3 | I33: =IFERROR(INDEX('Pitcher Leaders'!$B$6:$B$255,MATCH(H33,'Pitcher Leaders'!$AA$6:$AA$255,0)),"") -> Justin Wrobleski | J33: =IFERROR(INDEX('Pitcher Leaders'!$C$6:$C$255,MATCH(I33,'Pitcher Leaders'!$B$6:$B$255,0)),"") -> Los Angeles Dodgers | K33: =IFERROR(INDEX('Pitcher Leaders'!$E$6:$E$255,MATCH(I33,'Pitcher Leaders'!$B$6:$B$255,0)),"") -> 7 | L33: =IFERROR(INDEX('Pitcher Leaders'!$X$6:$X$255,MATCH(I33,'Pitcher Leaders'!$B$6:$B$255,0)),"") -> 2.35
B34: 4 | C34: =IFERROR(INDEX('Batter Leaders'!$B$6:$B$255,MATCH(B34,'Batter Leaders'!$AA$6:$AA$255,0)),"") -> Miguel Rojas | D34: =IFERROR(INDEX('Batter Leaders'!$C$6:$C$255,MATCH(C34,'Batter Leaders'!$B$6:$B$255,0)),"") -> Los Angeles Dodgers | E34: =IFERROR(INDEX('Batter Leaders'!$E$6:$E$255,MATCH(C34,'Batter Leaders'!$B$6:$B$255,0)),"") -> 5 | F34: =IFERROR(INDEX('Batter Leaders'!$T$6:$T$255,MATCH(C34,'Batter Leaders'!$B$6:$B$255,0)),"") -> 1.4 | H34: 4 | I34: =IFERROR(INDEX('Pitcher Leaders'!$B$6:$B$255,MATCH(H34,'Pitcher Leaders'!$AA$6:$AA$255,0)),"") -> Blake Snell | J34: =IFERROR(INDEX('Pitcher Leaders'!$C$6:$C$255,MATCH(I34,'Pitcher Leaders'!$B$6:$B$255,0)),"") -> Los Angeles Dodgers | K34: =IFERROR(INDEX('Pitcher Leaders'!$E$6:$E$255,MATCH(I34,'Pitcher Leaders'!$B$6:$B$255,0)),"") -> 6 | L34: =IFERROR(INDEX('Pitcher Leaders'!$X$6:$X$255,MATCH(I34,'Pitcher Leaders'!$B$6:$B$255,0)),"") -> 2.35
B35: 5 | C35: =IFERROR(INDEX('Batter Leaders'!$B$6:$B$255,MATCH(B35,'Batter Leaders'!$AA$6:$AA$255,0)),"") -> Will Smith | D35: =IFERROR(INDEX('Batter Leaders'!$C$6:$C$255,MATCH(C35,'Batter Leaders'!$B$6:$B$255,0)),"") -> Los Angeles Dodgers | E35: =IFERROR(INDEX('Batter Leaders'!$E$6:$E$255,MATCH(C35,'Batter Leaders'!$B$6:$B$255,0)),"") -> 6 | F35: =IFERROR(INDEX('Batter Leaders'!$T$6:$T$255,MATCH(C35,'Batter Leaders'!$B$6:$B$255,0)),"") -> 1.3333333 | H35: 5 | I35: =IFERROR(INDEX('Pitcher Leaders'!$B$6:$B$255,MATCH(H35,'Pitcher Leaders'!$AA$6:$AA$255,0)),"") -> Max Scherzer | J35: =IFERROR(INDEX('Pitcher Leaders'!$C$6:$C$255,MATCH(I35,'Pitcher Leaders'!$B$6:$B$255,0)),"") -> Toronto Blue Jays | K35: =IFERROR(INDEX('Pitcher Leaders'!$E$6:$E$255,MATCH(I35,'Pitcher Leaders'!$B$6:$B$255,0)),"") -> 18 | L35: =IFERROR(INDEX('Pitcher Leaders'!$X$6:$X$255,MATCH(I35,'Pitcher Leaders'!$B$6:$B$255,0)),"") -> 2.4076923
B37: Ties are broken by order of appearance. Change qualification thresholds on the Lists tab (C11:C12).

Sheet Team Offense
B2: Team Offense
B3: Batting production by team. Team list builds automatically from the data (up to 30 teams).
B5: Team | C5: G | D5: PA | E5: AB | F5: R | G5: H | H5: 1B | I5: 2B | J5: 3B | K5: HR | L5: TB | M5: BB | N5: IBB | O5: HBP | P5: K | Q5: SF | R5: SH | S5: DP | T5: SB | U5: CS | V5: AVG | W5: OBP | X5: SLG | Y5: OPS | Z5: ISO | AA5: BABIP | AB5: K% | AC5: BB% | AD5: BB/K | AE5: Pitches / PA | AF5: SB%
B6: {=IFERROR(INDEX(pbp_BatTeam,MATCH(0,COUNTIF($B$5:B5,pbp_BatTeam),0)),"")} -> Los Angeles Dodgers | C6: =IF($B6="","",SUMPRODUCT((pbp_BatTeam=$B6)*(LEN(pbp_Inning)=2)*(LEFT(pbp_Inning,1)="1")*(((pbp_Inning<>pbp_InningPrev)+(pbp_GameID<>pbp_GameIDPrev))>0))) -> 1 | D6: =IF($B6="","",SUMPRODUCT(COUNTIFS(pbp_PlayType,EM_Type,pbp_BatTeam,$B6)*EM_PA)) -> 48 | E6: =IF($B6="","",SUMPRODUCT(COUNTIFS(pbp_PlayType,EM_Type,pbp_BatTeam,$B6)*EM_AB)) -> 41 | F6: =IF($B6="","",SUMIFS(pbp_Runs,pbp_BatTeam,$B6)) -> 5 | G6: =IF($B6="","",SUMPRODUCT(COUNTIFS(pbp_PlayType,EM_Type,pbp_BatTeam,$B6)*EM_H)) -> 11 | H6: =IF($B6="","",SUMPRODUCT(COUNTIFS(pbp_PlayType,EM_Type,pbp_BatTeam,$B6)*EM_1B)) -> 7 | I6: =IF($B6="","",SUMPRODUCT(COUNTIFS(pbp_PlayType,EM_Type,pbp_BatTeam,$B6)*EM_2B)) -> 1 | J6: =IF($B6="","",SUMPRODUCT(COUNTIFS(pbp_PlayType,EM_Type,pbp_BatTeam,$B6)*EM_3B)) -> 0 | K6: =IF($B6="","",SUMPRODUCT(COUNTIFS(pbp_PlayType,EM_Type,pbp_BatTeam,$B6)*EM_HR)) -> 3 | L6: =IF($B6="","",H6+2*I6+3*J6+4*K6) -> 21 | M6: =IF($B6="","",SUMPRODUCT(COUNTIFS(pbp_PlayType,EM_Type,pbp_BatTeam,$B6)*EM_BB)) -> 5 | N6: =IF($B6="","",SUMPRODUCT(COUNTIFS(pbp_PlayType,EM_Type,pbp_BatTeam,$B6)*EM_IBB)) -> 0 | O6: =IF($B6="","",SUMPRODUCT(COUNTIFS(pbp_PlayType,EM_Type,pbp_BatTeam,$B6)*EM_HBP)) -> 0 | P6: =IF($B6="","",COUNTIFS(pbp_PlayType,"?*",pbp_Desc,"*struck out*",pbp_BatTeam,$B6)) -> 5 | Q6: =IF($B6="","",SUMPRODUCT(COUNTIFS(pbp_PlayType,EM_Type,pbp_BatTeam,$B6)*EM_SF)) -> 2 | R6: =IF($B6="","",SUMPRODUCT(COUNTIFS(pbp_PlayType,EM_Type,pbp_BatTeam,$B6)*EM_SH)) -> 0 | S6: =IF($B6="","",SUMPRODUCT(COUNTIFS(pbp_PlayType,EM_Type,pbp_BatTeam,$B6)*EM_DP)) -> 1 | T6: =IF($B6="","",SUMIFS(pbp_SB,pbp_BatTeam,$B6)) -> 0 | U6: =IF($B6="","",SUMIFS(pbp_CS,pbp_BatTeam,$B6)) -> 0 | V6: =IF($B6="","",IF((E6)=0,"",(G6)/(E6))) -> 0.26829268 | W6: =IF($B6="","",IF(((E6+M6+O6+Q6))=0,"",((G6+M6+O6))/((E6+M6+O6+Q6)))) -> 0.33333333 | X6: =IF($B6="","",IF((E6)=0,"",(L6)/(E6))) -> 0.51219512 | Y6: =IF($B6="","",IF(E6=0,"",W6+X6)) -> 0.84552846 | Z6: =IF($B6="","",IF(E6=0,"",X6-V6)) -> 0.24390244 | AA6: =IF($B6="","",IF(((E6-P6-K6+Q6))=0,"",((G6-K6))/((E6-P6-K6+Q6)))) -> 0.22857143 | AB6: =IF($B6="","",IF((D6)=0,"",(P6)/(D6))) -> 0.10416667 | AC6: =IF($B6="","",IF((D6)=0,"",(M6)/(D6))) -> 0.10416667 | AD6: =IF($B6="","",IF((P6)=0,"",(M6)/(P6))) -> 1 | AE6: =IF($B6="","",IF((D6)=0,"",(SUMIFS(pbp_Pitches,pbp_BatTeam,$B6,pbp_PlayType,"?*"))/(D6))) -> 3.5833333 | AF6: =IF($B6="","",IF(((T6+U6))=0,"",(T6)/((T6+U6))))
B7: {=IFERROR(INDEX(pbp_BatTeam,MATCH(0,COUNTIF($B$5:B6,pbp_BatTeam),0)),"")} -> Toronto Blue Jays | C7: =IF($B7="","",SUMPRODUCT((pbp_BatTeam=$B7)*(LEN(pbp_Inning)=2)*(LEFT(pbp_Inning,1)="1")*(((pbp_Inning<>pbp_InningPrev)+(pbp_GameID<>pbp_GameIDPrev))>0))) -> 1 | D7: =IF($B7="","",SUMPRODUCT(COUNTIFS(pbp_PlayType,EM_Type,pbp_BatTeam,$B7)*EM_PA)) -> 51 | E7: =IF($B7="","",SUMPRODUCT(COUNTIFS(pbp_PlayType,EM_Type,pbp_BatTeam,$B7)*EM_AB)) -> 43 | F7: =IF($B7="","",SUMIFS(pbp_Runs,pbp_BatTeam,$B7)) -> 4 | G7: =IF($B7="","",SUMPRODUCT(COUNTIFS(pbp_PlayType,EM_Type,pbp_BatTeam,$B7)*EM_H)) -> 14 | H7: =IF($B7="","",SUMPRODUCT(COUNTIFS(pbp_PlayType,EM_Type,pbp_BatTeam,$B7)*EM_1B)) -> 10 | I7: =IF($B7="","",SUMPRODUCT(COUNTIFS(pbp_PlayType,EM_Type,pbp_BatTeam,$B7)*EM_2B)) -> 3 | J7: =IF($B7="","",SUMPRODUCT(COUNTIFS(pbp_PlayType,EM_Type,pbp_BatTeam,$B7)*EM_3B)) -> 0 | K7: =IF($B7="","",SUMPRODUCT(COUNTIFS(pbp_PlayType,EM_Type,pbp_BatTeam,$B7)*EM_HR)) -> 1 | L7: =IF($B7="","",H7+2*I7+3*J7+4*K7) -> 20 | M7: =IF($B7="","",SUMPRODUCT(COUNTIFS(pbp_PlayType,EM_Type,pbp_BatTeam,$B7)*EM_BB)) -> 4 | N7: =IF($B7="","",SUMPRODUCT(COUNTIFS(pbp_PlayType,EM_Type,pbp_BatTeam,$B7)*EM_IBB)) -> 1 | O7: =IF($B7="","",SUMPRODUCT(COUNTIFS(pbp_PlayType,EM_Type,pbp_BatTeam,$B7)*EM_HBP)) -> 2 | P7: =IF($B7="","",COUNTIFS(pbp_PlayType,"?*",pbp_Desc,"*struck out*",pbp_BatTeam,$B7)) -> 12 | Q7: =IF($B7="","",SUMPRODUCT(COUNTIFS(pbp_PlayType,EM_Type,pbp_BatTeam,$B7)*EM_SF)) -> 0 | R7: =IF($B7="","",SUMPRODUCT(COUNTIFS(pbp_PlayType,EM_Type,pbp_BatTeam,$B7)*EM_SH)) -> 2 | S7: =IF($B7="","",SUMPRODUCT(COUNTIFS(pbp_PlayType,EM_Type,pbp_BatTeam,$B7)*EM_DP)) -> 2 | T7: =IF($B7="","",SUMIFS(pbp_SB,pbp_BatTeam,$B7)) -> 1 | U7: =IF($B7="","",SUMIFS(pbp_CS,pbp_BatTeam,$B7)) -> 1 | V7: =IF($B7="","",IF((E7)=0,"",(G7)/(E7))) -> 0.3255814 | W7: =IF($B7="","",IF(((E7+M7+O7+Q7))=0,"",((G7+M7+O7))/((E7+M7+O7+Q7)))) -> 0.40816327 | X7: =IF($B7="","",IF((E7)=0,"",(L7)/(E7))) -> 0.46511628 | Y7: =IF($B7="","",IF(E7=0,"",W7+X7)) -> 0.87327954 | Z7: =IF($B7="","",IF(E7=0,"",X7-V7)) -> 0.13953488 | AA7: =IF($B7="","",IF(((E7-P7-K7+Q7))=0,"",((G7-K7))/((E7-P7-K7+Q7)))) -> 0.43333333 | AB7: =IF($B7="","",IF((D7)=0,"",(P7)/(D7))) -> 0.23529412 | AC7: =IF($B7="","",IF((D7)=0,"",(M7)/(D7))) -> 0.078431373 | AD7: =IF($B7="","",IF((P7)=0,"",(M7)/(P7))) -> 0.33333333 | AE7: =IF($B7="","",IF((D7)=0,"",(SUMIFS(pbp_Pitches,pbp_BatTeam,$B7,pbp_PlayType,"?*"))/(D7))) -> 3.7647059 | AF7: =IF($B7="","",IF(((T7+U7))=0,"",(T7)/((T7+U7)))) -> 0.5
B8: {=IFERROR(INDEX(pbp_BatTeam,MATCH(0,COUNTIF($B$5:B7,pbp_BatTeam),0)),"")} | C8: =IF($B8="","",SUMPRODUCT((pbp_BatTeam=$B8)*(LEN(pbp_Inning)=2)*(LEFT(pbp_Inning,1)="1")*(((pbp_Inning<>pbp_InningPrev)+(pbp_GameID<>pbp_GameIDPrev))>0))) | D8: =IF($B8="","",SUMPRODUCT(COUNTIFS(pbp_PlayType,EM_Type,pbp_BatTeam,$B8)*EM_PA)) | E8: =IF($B8="","",SUMPRODUCT(COUNTIFS(pbp_PlayType,EM_Type,pbp_BatTeam,$B8)*EM_AB)) | F8: =IF($B8="","",SUMIFS(pbp_Runs,pbp_BatTeam,$B8)) | G8: =IF($B8="","",SUMPRODUCT(COUNTIFS(pbp_PlayType,EM_Type,pbp_BatTeam,$B8)*EM_H)) | H8: =IF($B8="","",SUMPRODUCT(COUNTIFS(pbp_PlayType,EM_Type,pbp_BatTeam,$B8)*EM_1B)) | I8: =IF($B8="","",SUMPRODUCT(COUNTIFS(pbp_PlayType,EM_Type,pbp_BatTeam,$B8)*EM_2B)) | J8: =IF($B8="","",SUMPRODUCT(COUNTIFS(pbp_PlayType,EM_Type,pbp_BatTeam,$B8)*EM_3B)) | K8: =IF($B8="","",SUMPRODUCT(COUNTIFS(pbp_PlayType,EM_Type,pbp_BatTeam,$B8)*EM_HR)) | L8: =IF($B8="","",H8+2*I8+3*J8+4*K8) | M8: =IF($B8="","",SUMPRODUCT(COUNTIFS(pbp_PlayType,EM_Type,pbp_BatTeam,$B8)*EM_BB)) | N8: =IF($B8="","",SUMPRODUCT(COUNTIFS(pbp_PlayType,EM_Type,pbp_BatTeam,$B8)*EM_IBB)) | O8: =IF($B8="","",SUMPRODUCT(COUNTIFS(pbp_PlayType,EM_Type,pbp_BatTeam,$B8)*EM_HBP)) | P8: =IF($B8="","",COUNTIFS(pbp_PlayType,"?*",pbp_Desc,"*struck out*",pbp_BatTeam,$B8)) | Q8: =IF($B8="","",SUMPRODUCT(COUNTIFS(pbp_PlayType,EM_Type,pbp_BatTeam,$B8)*EM_SF)) | R8: =IF($B8="","",SUMPRODUCT(COUNTIFS(pbp_PlayType,EM_Type,pbp_BatTeam,$B8)*EM_SH)) | S8: =IF($B8="","",SUMPRODUCT(COUNTIFS(pbp_PlayType,EM_Type,pbp_BatTeam,$B8)*EM_DP)) | T8: =IF($B8="","",SUMIFS(pbp_SB,pbp_BatTeam,$B8)) | U8: =IF($B8="","",SUMIFS(pbp_CS,pbp_BatTeam,$B8)) | V8: =IF($B8="","",IF((E8)=0,"",(G8)/(E8))) | W8: =IF($B8="","",IF(((E8+M8+O8+Q8))=0,"",((G8+M8+O8))/((E8+M8+O8+Q8)))) | X8: =IF($B8="","",IF((E8)=0,"",(L8)/(E8))) | Y8: =IF($B8="","",IF(E8=0,"",W8+X8)) | Z8: =IF($B8="","",IF(E8=0,"",X8-V8)) | AA8: =IF($B8="","",IF(((E8-P8-K8+Q8))=0,"",((G8-K8))/((E8-P8-K8+Q8)))) | AB8: =IF($B8="","",IF((D8)=0,"",(P8)/(D8))) | AC8: =IF($B8="","",IF((D8)=0,"",(M8)/(D8))) | AD8: =IF($B8="","",IF((P8)=0,"",(M8)/(P8))) | AE8: =IF($B8="","",IF((D8)=0,"",(SUMIFS(pbp_Pitches,pbp_BatTeam,$B8,pbp_PlayType,"?*"))/(D8))) | AF8: =IF($B8="","",IF(((T8+U8))=0,"",(T8)/((T8+U8))))
B9: {=IFERROR(INDEX(pbp_BatTeam,MATCH(0,COUNTIF($B$5:B8,pbp_BatTeam),0)),"")} | C9: =IF($B9="","",SUMPRODUCT((pbp_BatTeam=$B9)*(LEN(pbp_Inning)=2)*(LEFT(pbp_Inning,1)="1")*(((pbp_Inning<>pbp_InningPrev)+(pbp_GameID<>pbp_GameIDPrev))>0))) | D9: =IF($B9="","",SUMPRODUCT(COUNTIFS(pbp_PlayType,EM_Type,pbp_BatTeam,$B9)*EM_PA)) | E9: =IF($B9="","",SUMPRODUCT(COUNTIFS(pbp_PlayType,EM_Type,pbp_BatTeam,$B9)*EM_AB)) | F9: =IF($B9="","",SUMIFS(pbp_Runs,pbp_BatTeam,$B9)) | G9: =IF($B9="","",SUMPRODUCT(COUNTIFS(pbp_PlayType,EM_Type,pbp_BatTeam,$B9)*EM_H)) | H9: =IF($B9="","",SUMPRODUCT(COUNTIFS(pbp_PlayType,EM_Type,pbp_BatTeam,$B9)*EM_1B)) | I9: =IF($B9="","",SUMPRODUCT(COUNTIFS(pbp_PlayType,EM_Type,pbp_BatTeam,$B9)*EM_2B)) | J9: =IF($B9="","",SUMPRODUCT(COUNTIFS(pbp_PlayType,EM_Type,pbp_BatTeam,$B9)*EM_3B)) | K9: =IF($B9="","",SUMPRODUCT(COUNTIFS(pbp_PlayType,EM_Type,pbp_BatTeam,$B9)*EM_HR)) | L9: =IF($B9="","",H9+2*I9+3*J9+4*K9) | M9: =IF($B9="","",SUMPRODUCT(COUNTIFS(pbp_PlayType,EM_Type,pbp_BatTeam,$B9)*EM_BB)) | N9: =IF($B9="","",SUMPRODUCT(COUNTIFS(pbp_PlayType,EM_Type,pbp_BatTeam,$B9)*EM_IBB)) | O9: =IF($B9="","",SUMPRODUCT(COUNTIFS(pbp_PlayType,EM_Type,pbp_BatTeam,$B9)*EM_HBP)) | P9: =IF($B9="","",COUNTIFS(pbp_PlayType,"?*",pbp_Desc,"*struck out*",pbp_BatTeam,$B9)) | Q9: =IF($B9="","",SUMPRODUCT(COUNTIFS(pbp_PlayType,EM_Type,pbp_BatTeam,$B9)*EM_SF)) | R9: =IF($B9="","",SUMPRODUCT(COUNTIFS(pbp_PlayType,EM_Type,pbp_BatTeam,$B9)*EM_SH)) | S9: =IF($B9="","",SUMPRODUCT(COUNTIFS(pbp_PlayType,EM_Type,pbp_BatTeam,$B9)*EM_DP)) | T9: =IF($B9="","",SUMIFS(pbp_SB,pbp_BatTeam,$B9)) | U9: =IF($B9="","",SUMIFS(pbp_CS,pbp_BatTeam,$B9)) | V9: =IF($B9="","",IF((E9)=0,"",(G9)/(E9))) | W9: =IF($B9="","",IF(((E9+M9+O9+Q9))=0,"",((G9+M9+O9))/((E9+M9+O9+Q9)))) | X9: =IF($B9="","",IF((E9)=0,"",(L9)/(E9))) | Y9: =IF($B9="","",IF(E9=0,"",W9+X9)) | Z9: =IF($B9="","",IF(E9=0,"",X9-V9)) | AA9: =IF($B9="","",IF(((E9-P9-K9+Q9))=0,"",((G9-K9))/((E9-P9-K9+Q9)))) | AB9: =IF($B9="","",IF((D9)=0,"",(P9)/(D9))) | AC9: =IF($B9="","",IF((D9)=0,"",(M9)/(D9))) | AD9: =IF($B9="","",IF((P9)=0,"",(M9)/(P9))) | AE9: =IF($B9="","",IF((D9)=0,"",(SUMIFS(pbp_Pitches,pbp_BatTeam,$B9,pbp_PlayType,"?*"))/(D9))) | AF9: =IF($B9="","",IF(((T9+U9))=0,"",(T9)/((T9+U9))))
B10: {=IFERROR(INDEX(pbp_BatTeam,MATCH(0,COUNTIF($B$5:B9,pbp_BatTeam),0)),"")} | C10: =IF($B10="","",SUMPRODUCT((pbp_BatTeam=$B10)*(LEN(pbp_Inning)=2)*(LEFT(pbp_Inning,1)="1")*(((pbp_Inning<>pbp_InningPrev)+(pbp_GameID<>pbp_GameIDPrev))>0))) | D10: =IF($B10="","",SUMPRODUCT(COUNTIFS(pbp_PlayType,EM_Type,pbp_BatTeam,$B10)*EM_PA)) | E10: =IF($B10="","",SUMPRODUCT(COUNTIFS(pbp_PlayType,EM_Type,pbp_BatTeam,$B10)*EM_AB)) | F10: =IF($B10="","",SUMIFS(pbp_Runs,pbp_BatTeam,$B10)) | G10: =IF($B10="","",SUMPRODUCT(COUNTIFS(pbp_PlayType,EM_Type,pbp_BatTeam,$B10)*EM_H)) | H10: =IF($B10="","",SUMPRODUCT(COUNTIFS(pbp_PlayType,EM_Type,pbp_BatTeam,$B10)*EM_1B)) | I10: =IF($B10="","",SUMPRODUCT(COUNTIFS(pbp_PlayType,EM_Type,pbp_BatTeam,$B10)*EM_2B)) | J10: =IF($B10="","",SUMPRODUCT(COUNTIFS(pbp_PlayType,EM_Type,pbp_BatTeam,$B10)*EM_3B)) | K10: =IF($B10="","",SUMPRODUCT(COUNTIFS(pbp_PlayType,EM_Type,pbp_BatTeam,$B10)*EM_HR)) | L10: =IF($B10="","",H10+2*I10+3*J10+4*K10) | M10: =IF($B10="","",SUMPRODUCT(COUNTIFS(pbp_PlayType,EM_Type,pbp_BatTeam,$B10)*EM_BB)) | N10: =IF($B10="","",SUMPRODUCT(COUNTIFS(pbp_PlayType,EM_Type,pbp_BatTeam,$B10)*EM_IBB)) | O10: =IF($B10="","",SUMPRODUCT(COUNTIFS(pbp_PlayType,EM_Type,pbp_BatTeam,$B10)*EM_HBP)) | P10: =IF($B10="","",COUNTIFS(pbp_PlayType,"?*",pbp_Desc,"*struck out*",pbp_BatTeam,$B10)) | Q10: =IF($B10="","",SUMPRODUCT(COUNTIFS(pbp_PlayType,EM_Type,pbp_BatTeam,$B10)*EM_SF)) | R10: =IF($B10="","",SUMPRODUCT(COUNTIFS(pbp_PlayType,EM_Type,pbp_BatTeam,$B10)*EM_SH)) | S10: =IF($B10="","",SUMPRODUCT(COUNTIFS(pbp_PlayType,EM_Type,pbp_BatTeam,$B10)*EM_DP)) | T10: =IF($B10="","",SUMIFS(pbp_SB,pbp_BatTeam,$B10)) | U10: =IF($B10="","",SUMIFS(pbp_CS,pbp_BatTeam,$B10)) | V10: =IF($B10="","",IF((E10)=0,"",(G10)/(E10))) | W10: =IF($B10="","",IF(((E10+M10+O10+Q10))=0,"",((G10+M10+O10))/((E10+M10+O10+Q10)))) | X10: =IF($B10="","",IF((E10)=0,"",(L10)/(E10))) | Y10: =IF($B10="","",IF(E10=0,"",W10+X10)) | Z10: =IF($B10="","",IF(E10=0,"",X10-V10)) | AA10: =IF($B10="","",IF(((E10-P10-K10+Q10))=0,"",((G10-K10))/((E10-P10-K10+Q10)))) | AB10: =IF($B10="","",IF((D10)=0,"",(P10)/(D10))) | AC10: =IF($B10="","",IF((D10)=0,"",(M10)/(D10))) | AD10: =IF($B10="","",IF((P10)=0,"",(M10)/(P10))) | AE10: =IF($B10="","",IF((D10)=0,"",(SUMIFS(pbp_Pitches,pbp_BatTeam,$B10,pbp_PlayType,"?*"))/(D10))) | AF10: =IF($B10="","",IF(((T10+U10))=0,"",(T10)/((T10+U10))))
B11: {=IFERROR(INDEX(pbp_BatTeam,MATCH(0,COUNTIF($B$5:B10,pbp_BatTeam),0)),"")} | C11: =IF($B11="","",SUMPRODUCT((pbp_BatTeam=$B11)*(LEN(pbp_Inning)=2)*(LEFT(pbp_Inning,1)="1")*(((pbp_Inning<>pbp_InningPrev)+(pbp_GameID<>pbp_GameIDPrev))>0))) | D11: =IF($B11="","",SUMPRODUCT(COUNTIFS(pbp_PlayType,EM_Type,pbp_BatTeam,$B11)*EM_PA)) | E11: =IF($B11="","",SUMPRODUCT(COUNTIFS(pbp_PlayType,EM_Type,pbp_BatTeam,$B11)*EM_AB)) | F11: =IF($B11="","",SUMIFS(pbp_Runs,pbp_BatTeam,$B11)) | G11: =IF($B11="","",SUMPRODUCT(COUNTIFS(pbp_PlayType,EM_Type,pbp_BatTeam,$B11)*EM_H)) | H11: =IF($B11="","",SUMPRODUCT(COUNTIFS(pbp_PlayType,EM_Type,pbp_BatTeam,$B11)*EM_1B)) | I11: =IF($B11="","",SUMPRODUCT(COUNTIFS(pbp_PlayType,EM_Type,pbp_BatTeam,$B11)*EM_2B)) | J11: =IF($B11="","",SUMPRODUCT(COUNTIFS(pbp_PlayType,EM_Type,pbp_BatTeam,$B11)*EM_3B)) | K11: =IF($B11="","",SUMPRODUCT(COUNTIFS(pbp_PlayType,EM_Type,pbp_BatTeam,$B11)*EM_HR)) | L11: =IF($B11="","",H11+2*I11+3*J11+4*K11) | M11: =IF($B11="","",SUMPRODUCT(COUNTIFS(pbp_PlayType,EM_Type,pbp_BatTeam,$B11)*EM_BB)) | N11: =IF($B11="","",SUMPRODUCT(COUNTIFS(pbp_PlayType,EM_Type,pbp_BatTeam,$B11)*EM_IBB)) | O11: =IF($B11="","",SUMPRODUCT(COUNTIFS(pbp_PlayType,EM_Type,pbp_BatTeam,$B11)*EM_HBP)) | P11: =IF($B11="","",COUNTIFS(pbp_PlayType,"?*",pbp_Desc,"*struck out*",pbp_BatTeam,$B11)) | Q11: =IF($B11="","",SUMPRODUCT(COUNTIFS(pbp_PlayType,EM_Type,pbp_BatTeam,$B11)*EM_SF)) | R11: =IF($B11="","",SUMPRODUCT(COUNTIFS(pbp_PlayType,EM_Type,pbp_BatTeam,$B11)*EM_SH)) | S11: =IF($B11="","",SUMPRODUCT(COUNTIFS(pbp_PlayType,EM_Type,pbp_BatTeam,$B11)*EM_DP)) | T11: =IF($B11="","",SUMIFS(pbp_SB,pbp_BatTeam,$B11)) | U11: =IF($B11="","",SUMIFS(pbp_CS,pbp_BatTeam,$B11)) | V11: =IF($B11="","",IF((E11)=0,"",(G11)/(E11))) | W11: =IF($B11="","",IF(((E11+M11+O11+Q11))=0,"",((G11+M11+O11))/((E11+M11+O11+Q11)))) | X11: =IF($B11="","",IF((E11)=0,"",(L11)/(E11))) | Y11: =IF($B11="","",IF(E11=0,"",W11+X11)) | Z11: =IF($B11="","",IF(E11=0,"",X11-V11)) | AA11: =IF($B11="","",IF(((E11-P11-K11+Q11))=0,"",((G11-K11))/((E11-P11-K11+Q11)))) | AB11: =IF($B11="","",IF((D11)=0,"",(P11)/(D11))) | AC11: =IF($B11="","",IF((D11)=0,"",(M11)/(D11))) | AD11: =IF($B11="","",IF((P11)=0,"",(M11)/(P11))) | AE11: =IF($B11="","",IF((D11)=0,"",(SUMIFS(pbp_Pitches,pbp_BatTeam,$B11,pbp_PlayType,"?*"))/(D11))) | AF11: =IF($B11="","",IF(((T11+U11))=0,"",(T11)/((T11+U11))))
B12: {=IFERROR(INDEX(pbp_BatTeam,MATCH(0,COUNTIF($B$5:B11,pbp_BatTeam),0)),"")} | C12: =IF($B12="","",SUMPRODUCT((pbp_BatTeam=$B12)*(LEN(pbp_Inning)=2)*(LEFT(pbp_Inning,1)="1")*(((pbp_Inning<>pbp_InningPrev)+(pbp_GameID<>pbp_GameIDPrev))>0))) | D12: =IF($B12="","",SUMPRODUCT(COUNTIFS(pbp_PlayType,EM_Type,pbp_BatTeam,$B12)*EM_PA)) | E12: =IF($B12="","",SUMPRODUCT(COUNTIFS(pbp_PlayType,EM_Type,pbp_BatTeam,$B12)*EM_AB)) | F12: =IF($B12="","",SUMIFS(pbp_Runs,pbp_BatTeam,$B12)) | G12: =IF($B12="","",SUMPRODUCT(COUNTIFS(pbp_PlayType,EM_Type,pbp_BatTeam,$B12)*EM_H)) | H12: =IF($B12="","",SUMPRODUCT(COUNTIFS(pbp_PlayType,EM_Type,pbp_BatTeam,$B12)*EM_1B)) | I12: =IF($B12="","",SUMPRODUCT(COUNTIFS(pbp_PlayType,EM_Type,pbp_BatTeam,$B12)*EM_2B)) | J12: =IF($B12="","",SUMPRODUCT(COUNTIFS(pbp_PlayType,EM_Type,pbp_BatTeam,$B12)*EM_3B)) | K12: =IF($B12="","",SUMPRODUCT(COUNTIFS(pbp_PlayType,EM_Type,pbp_BatTeam,$B12)*EM_HR)) | L12: =IF($B12="","",H12+2*I12+3*J12+4*K12) | M12: =IF($B12="","",SUMPRODUCT(COUNTIFS(pbp_PlayType,EM_Type,pbp_BatTeam,$B12)*EM_BB)) | N12: =IF($B12="","",SUMPRODUCT(COUNTIFS(pbp_PlayType,EM_Type,pbp_BatTeam,$B12)*EM_IBB)) | O12: =IF($B12="","",SUMPRODUCT(COUNTIFS(pbp_PlayType,EM_Type,pbp_BatTeam,$B12)*EM_HBP)) | P12: =IF($B12="","",COUNTIFS(pbp_PlayType,"?*",pbp_Desc,"*struck out*",pbp_BatTeam,$B12)) | Q12: =IF($B12="","",SUMPRODUCT(COUNTIFS(pbp_PlayType,EM_Type,pbp_BatTeam,$B12)*EM_SF)) | R12: =IF($B12="","",SUMPRODUCT(COUNTIFS(pbp_PlayType,EM_Type,pbp_BatTeam,$B12)*EM_SH)) | S12: =IF($B12="","",SUMPRODUCT(COUNTIFS(pbp_PlayType,EM_Type,pbp_BatTeam,$B12)*EM_DP)) | T12: =IF($B12="","",SUMIFS(pbp_SB,pbp_BatTeam,$B12)) | U12: =IF($B12="","",SUMIFS(pbp_CS,pbp_BatTeam,$B12)) | V12: =IF($B12="","",IF((E12)=0,"",(G12)/(E12))) | W12: =IF($B12="","",IF(((E12+M12+O12+Q12))=0,"",((G12+M12+O12))/((E12+M12+O12+Q12)))) | X12: =IF($B12="","",IF((E12)=0,"",(L12)/(E12))) | Y12: =IF($B12="","",IF(E12=0,"",W12+X12)) | Z12: =IF($B12="","",IF(E12=0,"",X12-V12)) | AA12: =IF($B12="","",IF(((E12-P12-K12+Q12))=0,"",((G12-K12))/((E12-P12-K12+Q12)))) | AB12: =IF($B12="","",IF((D12)=0,"",(P12)/(D12))) | AC12: =IF($B12="","",IF((D12)=0,"",(M12)/(D12))) | AD12: =IF($B12="","",IF((P12)=0,"",(M12)/(P12))) | AE12: =IF($B12="","",IF((D12)=0,"",(SUMIFS(pbp_Pitches,pbp_BatTeam,$B12,pbp_PlayType,"?*"))/(D12))) | AF12: =IF($B12="","",IF(((T12+U12))=0,"",(T12)/((T12+U12))))
B13: {=IFERROR(INDEX(pbp_BatTeam,MATCH(0,COUNTIF($B$5:B12,pbp_BatTeam),0)),"")} | C13: =IF($B13="","",SUMPRODUCT((pbp_BatTeam=$B13)*(LEN(pbp_Inning)=2)*(LEFT(pbp_Inning,1)="1")*(((pbp_Inning<>pbp_InningPrev)+(pbp_GameID<>pbp_GameIDPrev))>0))) | D13: =IF($B13="","",SUMPRODUCT(COUNTIFS(pbp_PlayType,EM_Type,pbp_BatTeam,$B13)*EM_PA)) | E13: =IF($B13="","",SUMPRODUCT(COUNTIFS(pbp_PlayType,EM_Type,pbp_BatTeam,$B13)*EM_AB)) | F13: =IF($B13="","",SUMIFS(pbp_Runs,pbp_BatTeam,$B13)) | G13: =IF($B13="","",SUMPRODUCT(COUNTIFS(pbp_PlayType,EM_Type,pbp_BatTeam,$B13)*EM_H)) | H13: =IF($B13="","",SUMPRODUCT(COUNTIFS(pbp_PlayType,EM_Type,pbp_BatTeam,$B13)*EM_1B)) | I13: =IF($B13="","",SUMPRODUCT(COUNTIFS(pbp_PlayType,EM_Type,pbp_BatTeam,$B13)*EM_2B)) | J13: =IF($B13="","",SUMPRODUCT(COUNTIFS(pbp_PlayType,EM_Type,pbp_BatTeam,$B13)*EM_3B)) | K13: =IF($B13="","",SUMPRODUCT(COUNTIFS(pbp_PlayType,EM_Type,pbp_BatTeam,$B13)*EM_HR)) | L13: =IF($B13="","",H13+2*I13+3*J13+4*K13) | M13: =IF($B13="","",SUMPRODUCT(COUNTIFS(pbp_PlayType,EM_Type,pbp_BatTeam,$B13)*EM_BB)) | N13: =IF($B13="","",SUMPRODUCT(COUNTIFS(pbp_PlayType,EM_Type,pbp_BatTeam,$B13)*EM_IBB)) | O13: =IF($B13="","",SUMPRODUCT(COUNTIFS(pbp_PlayType,EM_Type,pbp_BatTeam,$B13)*EM_HBP)) | P13: =IF($B13="","",COUNTIFS(pbp_PlayType,"?*",pbp_Desc,"*struck out*",pbp_BatTeam,$B13)) | Q13: =IF($B13="","",SUMPRODUCT(COUNTIFS(pbp_PlayType,EM_Type,pbp_BatTeam,$B13)*EM_SF)) | R13: =IF($B13="","",SUMPRODUCT(COUNTIFS(pbp_PlayType,EM_Type,pbp_BatTeam,$B13)*EM_SH)) | S13: =IF($B13="","",SUMPRODUCT(COUNTIFS(pbp_PlayType,EM_Type,pbp_BatTeam,$B13)*EM_DP)) | T13: =IF($B13="","",SUMIFS(pbp_SB,pbp_BatTeam,$B13)) | U13: =IF($B13="","",SUMIFS(pbp_CS,pbp_BatTeam,$B13)) | V13: =IF($B13="","",IF((E13)=0,"",(G13)/(E13))) | W13: =IF($B13="","",IF(((E13+M13+O13+Q13))=0,"",((G13+M13+O13))/((E13+M13+O13+Q13)))) | X13: =IF($B13="","",IF((E13)=0,"",(L13)/(E13))) | Y13: =IF($B13="","",IF(E13=0,"",W13+X13)) | Z13: =IF($B13="","",IF(E13=0,"",X13-V13)) | AA13: =IF($B13="","",IF(((E13-P13-K13+Q13))=0,"",((G13-K13))/((E13-P13-K13+Q13)))) | AB13: =IF($B13="","",IF((D13)=0,"",(P13)/(D13))) | AC13: =IF($B13="","",IF((D13)=0,"",(M13)/(D13))) | AD13: =IF($B13="","",IF((P13)=0,"",(M13)/(P13))) | AE13: =IF($B13="","",IF((D13)=0,"",(SUMIFS(pbp_Pitches,pbp_BatTeam,$B13,pbp_PlayType,"?*"))/(D13))) | AF13: =IF($B13="","",IF(((T13+U13))=0,"",(T13)/((T13+U13))))
B14: {=IFERROR(INDEX(pbp_BatTeam,MATCH(0,COUNTIF($B$5:B13,pbp_BatTeam),0)),"")} | C14: =IF($B14="","",SUMPRODUCT((pbp_BatTeam=$B14)*(LEN(pbp_Inning)=2)*(LEFT(pbp_Inning,1)="1")*(((pbp_Inning<>pbp_InningPrev)+(pbp_GameID<>pbp_GameIDPrev))>0))) | D14: =IF($B14="","",SUMPRODUCT(COUNTIFS(pbp_PlayType,EM_Type,pbp_BatTeam,$B14)*EM_PA)) | E14: =IF($B14="","",SUMPRODUCT(COUNTIFS(pbp_PlayType,EM_Type,pbp_BatTeam,$B14)*EM_AB)) | F14: =IF($B14="","",SUMIFS(pbp_Runs,pbp_BatTeam,$B14)) | G14: =IF($B14="","",SUMPRODUCT(COUNTIFS(pbp_PlayType,EM_Type,pbp_BatTeam,$B14)*EM_H)) | H14: =IF($B14="","",SUMPRODUCT(COUNTIFS(pbp_PlayType,EM_Type,pbp_BatTeam,$B14)*EM_1B)) | I14: =IF($B14="","",SUMPRODUCT(COUNTIFS(pbp_PlayType,EM_Type,pbp_BatTeam,$B14)*EM_2B)) | J14: =IF($B14="","",SUMPRODUCT(COUNTIFS(pbp_PlayType,EM_Type,pbp_BatTeam,$B14)*EM_3B)) | K14: =IF($B14="","",SUMPRODUCT(COUNTIFS(pbp_PlayType,EM_Type,pbp_BatTeam,$B14)*EM_HR)) | L14: =IF($B14="","",H14+2*I14+3*J14+4*K14) | M14: =IF($B14="","",SUMPRODUCT(COUNTIFS(pbp_PlayType,EM_Type,pbp_BatTeam,$B14)*EM_BB)) | N14: =IF($B14="","",SUMPRODUCT(COUNTIFS(pbp_PlayType,EM_Type,pbp_BatTeam,$B14)*EM_IBB)) | O14: =IF($B14="","",SUMPRODUCT(COUNTIFS(pbp_PlayType,EM_Type,pbp_BatTeam,$B14)*EM_HBP)) | P14: =IF($B14="","",COUNTIFS(pbp_PlayType,"?*",pbp_Desc,"*struck out*",pbp_BatTeam,$B14)) | Q14: =IF($B14="","",SUMPRODUCT(COUNTIFS(pbp_PlayType,EM_Type,pbp_BatTeam,$B14)*EM_SF)) | R14: =IF($B14="","",SUMPRODUCT(COUNTIFS(pbp_PlayType,EM_Type,pbp_BatTeam,$B14)*EM_SH)) | S14: =IF($B14="","",SUMPRODUCT(COUNTIFS(pbp_PlayType,EM_Type,pbp_BatTeam,$B14)*EM_DP)) | T14: =IF($B14="","",SUMIFS(pbp_SB,pbp_BatTeam,$B14)) | U14: =IF($B14="","",SUMIFS(pbp_CS,pbp_BatTeam,$B14)) | V14: =IF($B14="","",IF((E14)=0,"",(G14)/(E14))) | W14: =IF($B14="","",IF(((E14+M14+O14+Q14))=0,"",((G14+M14+O14))/((E14+M14+O14+Q14)))) | X14: =IF($B14="","",IF((E14)=0,"",(L14)/(E14))) | Y14: =IF($B14="","",IF(E14=0,"",W14+X14)) | Z14: =IF($B14="","",IF(E14=0,"",X14-V14)) | AA14: =IF($B14="","",IF(((E14-P14-K14+Q14))=0,"",((G14-K14))/((E14-P14-K14+Q14)))) | AB14: =IF($B14="","",IF((D14)=0,"",(P14)/(D14))) | AC14: =IF($B14="","",IF((D14)=0,"",(M14)/(D14))) | AD14: =IF($B14="","",IF((P14)=0,"",(M14)/(P14))) | AE14: =IF($B14="","",IF((D14)=0,"",(SUMIFS(pbp_Pitches,pbp_BatTeam,$B14,pbp_PlayType,"?*"))/(D14))) | AF14: =IF($B14="","",IF(((T14+U14))=0,"",(T14)/((T14+U14))))
B15: {=IFERROR(INDEX(pbp_BatTeam,MATCH(0,COUNTIF($B$5:B14,pbp_BatTeam),0)),"")} | C15: =IF($B15="","",SUMPRODUCT((pbp_BatTeam=$B15)*(LEN(pbp_Inning)=2)*(LEFT(pbp_Inning,1)="1")*(((pbp_Inning<>pbp_InningPrev)+(pbp_GameID<>pbp_GameIDPrev))>0))) | D15: =IF($B15="","",SUMPRODUCT(COUNTIFS(pbp_PlayType,EM_Type,pbp_BatTeam,$B15)*EM_PA)) | E15: =IF($B15="","",SUMPRODUCT(COUNTIFS(pbp_PlayType,EM_Type,pbp_BatTeam,$B15)*EM_AB)) | F15: =IF($B15="","",SUMIFS(pbp_Runs,pbp_BatTeam,$B15)) | G15: =IF($B15="","",SUMPRODUCT(COUNTIFS(pbp_PlayType,EM_Type,pbp_BatTeam,$B15)*EM_H)) | H15: =IF($B15="","",SUMPRODUCT(COUNTIFS(pbp_PlayType,EM_Type,pbp_BatTeam,$B15)*EM_1B)) | I15: =IF($B15="","",SUMPRODUCT(COUNTIFS(pbp_PlayType,EM_Type,pbp_BatTeam,$B15)*EM_2B)) | J15: =IF($B15="","",SUMPRODUCT(COUNTIFS(pbp_PlayType,EM_Type,pbp_BatTeam,$B15)*EM_3B)) | K15: =IF($B15="","",SUMPRODUCT(COUNTIFS(pbp_PlayType,EM_Type,pbp_BatTeam,$B15)*EM_HR)) | L15: =IF($B15="","",H15+2*I15+3*J15+4*K15) | M15: =IF($B15="","",SUMPRODUCT(COUNTIFS(pbp_PlayType,EM_Type,pbp_BatTeam,$B15)*EM_BB)) | N15: =IF($B15="","",SUMPRODUCT(COUNTIFS(pbp_PlayType,EM_Type,pbp_BatTeam,$B15)*EM_IBB)) | O15: =IF($B15="","",SUMPRODUCT(COUNTIFS(pbp_PlayType,EM_Type,pbp_BatTeam,$B15)*EM_HBP)) | P15: =IF($B15="","",COUNTIFS(pbp_PlayType,"?*",pbp_Desc,"*struck out*",pbp_BatTeam,$B15)) | Q15: =IF($B15="","",SUMPRODUCT(COUNTIFS(pbp_PlayType,EM_Type,pbp_BatTeam,$B15)*EM_SF)) | R15: =IF($B15="","",SUMPRODUCT(COUNTIFS(pbp_PlayType,EM_Type,pbp_BatTeam,$B15)*EM_SH)) | S15: =IF($B15="","",SUMPRODUCT(COUNTIFS(pbp_PlayType,EM_Type,pbp_BatTeam,$B15)*EM_DP)) | T15: =IF($B15="","",SUMIFS(pbp_SB,pbp_BatTeam,$B15)) | U15: =IF($B15="","",SUMIFS(pbp_CS,pbp_BatTeam,$B15)) | V15: =IF($B15="","",IF((E15)=0,"",(G15)/(E15))) | W15: =IF($B15="","",IF(((E15+M15+O15+Q15))=0,"",((G15+M15+O15))/((E15+M15+O15+Q15)))) | X15: =IF($B15="","",IF((E15)=0,"",(L15)/(E15))) | Y15: =IF($B15="","",IF(E15=0,"",W15+X15)) | Z15: =IF($B15="","",IF(E15=0,"",X15-V15)) | AA15: =IF($B15="","",IF(((E15-P15-K15+Q15))=0,"",((G15-K15))/((E15-P15-K15+Q15)))) | AB15: =IF($B15="","",IF((D15)=0,"",(P15)/(D15))) | AC15: =IF($B15="","",IF((D15)=0,"",(M15)/(D15))) | AD15: =IF($B15="","",IF((P15)=0,"",(M15)/(P15))) | AE15: =IF($B15="","",IF((D15)=0,"",(SUMIFS(pbp_Pitches,pbp_BatTeam,$B15,pbp_PlayType,"?*"))/(D15))) | AF15: =IF($B15="","",IF(((T15+U15))=0,"",(T15)/((T15+U15))))
